[2025-03-03 11:16:13,040: INFO: main: >>>>> stage Data Ingestion Stage started <<<<<<]
[2025-03-03 11:16:13,042: INFO: common: yaml file: config/config.yaml loaded successfully]
[2025-03-03 11:16:13,042: INFO: common: yaml file: params.yaml loaded successfully]
[2025-03-03 11:16:13,043: ERROR: main: yaml file is empty]
Traceback (most recent call last):
  File "/Users/neerajbhauryal/Desktop/ML projects/DS-Project/src/DS_Project/utils/common.py", line 31, in read_yaml
    return ConfigBox(content)
  File "box/box.py", line 295, in box.box.Box.__init__
box.exceptions.BoxValueError: First argument must be mapping or iterable

During handling of the above exception, another exception occurred:

Traceback (most recent call last):
  File "/Users/neerajbhauryal/Desktop/ML projects/DS-Project/main.py", line 8, in <module>
    obj.initiate_data_ingestion()
  File "/Users/neerajbhauryal/Desktop/ML projects/DS-Project/src/DS_Project/pipeline/data_ingestion.py", line 12, in initiate_data_ingestion
    config=ConfigurationManager()
  File "/Users/neerajbhauryal/Desktop/ML projects/DS-Project/src/DS_Project/config/configuration.py", line 12, in __init__
    self.params = read_yaml(params_filepath)
  File "/Users/neerajbhauryal/Desktop/ML projects/DS-Project/venv/lib/python3.10/site-packages/ensure/main.py", line 872, in __call__
    return_val = self.f(*args, **kwargs)
  File "/Users/neerajbhauryal/Desktop/ML projects/DS-Project/src/DS_Project/utils/common.py", line 33, in read_yaml
    raise ValueError("yaml file is empty")
ValueError: yaml file is empty
[2025-03-03 11:17:37,938: INFO: main: >>>>> stage Data Ingestion Stage started <<<<<<]
[2025-03-03 11:17:37,940: INFO: common: yaml file: config/config.yaml loaded successfully]
[2025-03-03 11:17:37,940: INFO: common: yaml file: params.yaml loaded successfully]
[2025-03-03 11:17:37,941: INFO: common: yaml file: schema.yaml loaded successfully]
[2025-03-03 11:17:37,941: INFO: common: created directory at: artifacts]
[2025-03-03 11:17:37,941: INFO: common: created directory at: artifacts/data_ingestion]
[2025-03-03 11:17:38,443: INFO: data_ingestion: artifacts/data_ingestion/data.zip download! with following info: 
Connection: close
Content-Length: 23329
Cache-Control: max-age=300
Content-Security-Policy: default-src 'none'; style-src 'unsafe-inline'; sandbox
Content-Type: application/zip
ETag: "c69888a4ae59bc5a893392785a938ccd4937981c06ba8a9d6a21aa52b4ab5b6e"
Strict-Transport-Security: max-age=31536000
X-Content-Type-Options: nosniff
X-Frame-Options: deny
X-XSS-Protection: 1; mode=block
X-GitHub-Request-Id: 22C2:1D364:C8D1F9:E711DF:67C581C1
Accept-Ranges: bytes
Date: Mon, 03 Mar 2025 10:17:38 GMT
Via: 1.1 varnish
X-Served-By: cache-fra-eddf8230151-FRA
X-Cache: MISS
X-Cache-Hits: 0
X-Timer: S1740997058.271546,VS0,VE157
Vary: Authorization,Accept-Encoding,Origin
Access-Control-Allow-Origin: *
Cross-Origin-Resource-Policy: cross-origin
X-Fastly-Request-ID: ae6d4df3ab71e8be1ee8f7c22f8f588e5dd0cd1f
Expires: Mon, 03 Mar 2025 10:22:38 GMT
Source-Age: 0

]
[2025-03-03 11:17:38,449: INFO: main: >>>>>> stage Data Ingestion Stage completed <<<<<

x=======x]
[2025-03-03 16:22:27,822: INFO: main: >>>>> stage Data Ingestion Stage started <<<<<<]
[2025-03-03 16:22:27,824: INFO: common: yaml file: config/config.yaml loaded successfully]
[2025-03-03 16:22:27,826: INFO: common: yaml file: params.yaml loaded successfully]
[2025-03-03 16:22:27,828: INFO: common: yaml file: schema.yaml loaded successfully]
[2025-03-03 16:22:27,829: INFO: common: created directory at: artifacts]
[2025-03-03 16:22:27,829: INFO: common: created directory at: artifacts/data_ingestion]
[2025-03-03 16:22:27,829: INFO: data_ingestion: File already exists]
[2025-03-03 16:22:27,834: INFO: main: >>>>>> stage Data Ingestion Stage completed <<<<<

x=======x]
[2025-03-03 16:22:27,834: INFO: main: >>>>> stage Data Validation Stage started <<<<<<]
[2025-03-03 16:22:27,834: ERROR: main: 'DataValidationTrainingPipeline' object has no attribute 'initiate_data_ingestion']
Traceback (most recent call last):
  File "/Users/neerajbhauryal/Desktop/ML projects/DS-Project/main.py", line 20, in <module>
    obj.initiate_data_ingestion()
AttributeError: 'DataValidationTrainingPipeline' object has no attribute 'initiate_data_ingestion'
[2025-03-03 16:23:48,050: INFO: main: >>>>> stage Data Ingestion Stage started <<<<<<]
[2025-03-03 16:23:48,052: INFO: common: yaml file: config/config.yaml loaded successfully]
[2025-03-03 16:23:48,052: INFO: common: yaml file: params.yaml loaded successfully]
[2025-03-03 16:23:48,054: INFO: common: yaml file: schema.yaml loaded successfully]
[2025-03-03 16:23:48,054: INFO: common: created directory at: artifacts]
[2025-03-03 16:23:48,054: INFO: common: created directory at: artifacts/data_ingestion]
[2025-03-03 16:23:48,054: INFO: data_ingestion: File already exists]
[2025-03-03 16:23:48,056: INFO: main: >>>>>> stage Data Ingestion Stage completed <<<<<

x=======x]
[2025-03-03 16:23:48,056: INFO: main: >>>>> stage Data Validation Stage started <<<<<<]
[2025-03-03 16:23:48,058: INFO: common: yaml file: config/config.yaml loaded successfully]
[2025-03-03 16:23:48,059: INFO: common: yaml file: params.yaml loaded successfully]
[2025-03-03 16:23:48,060: INFO: common: yaml file: schema.yaml loaded successfully]
[2025-03-03 16:23:48,061: INFO: common: created directory at: artifacts]
[2025-03-03 16:23:48,061: ERROR: main: "'ConfigBox' object has no attribute 'data_validation'"]
Traceback (most recent call last):
  File "box/box.py", line 594, in box.box.Box.__getitem__
KeyError: 'data_validation'

The above exception was the direct cause of the following exception:

Traceback (most recent call last):
  File "box/box.py", line 633, in box.box.Box.__getattr__
  File "box/box.py", line 621, in box.box.Box.__getitem__
box.exceptions.BoxKeyError: "'data_validation'"

During handling of the above exception, another exception occurred:

Traceback (most recent call last):
  File "box/box.py", line 635, in box.box.Box.__getattr__
AttributeError: 'ConfigBox' object has no attribute 'data_validation'

The above exception was the direct cause of the following exception:

Traceback (most recent call last):
  File "box/config_box.py", line 29, in box.config_box.ConfigBox.__getattr__
  File "box/box.py", line 649, in box.box.Box.__getattr__
box.exceptions.BoxKeyError: "'ConfigBox' object has no attribute 'data_validation'"

During handling of the above exception, another exception occurred:

Traceback (most recent call last):
  File "box/box.py", line 594, in box.box.Box.__getitem__
KeyError: 'data_validation'

The above exception was the direct cause of the following exception:

Traceback (most recent call last):
  File "box/box.py", line 633, in box.box.Box.__getattr__
  File "box/box.py", line 621, in box.box.Box.__getitem__
box.exceptions.BoxKeyError: "'data_validation'"

During handling of the above exception, another exception occurred:

Traceback (most recent call last):
  File "box/box.py", line 635, in box.box.Box.__getattr__
AttributeError: 'ConfigBox' object has no attribute 'data_validation'

The above exception was the direct cause of the following exception:

Traceback (most recent call last):
  File "/Users/neerajbhauryal/Desktop/ML projects/DS-Project/main.py", line 20, in <module>
    obj.initiate_data_validation()
  File "/Users/neerajbhauryal/Desktop/ML projects/DS-Project/src/DS_Project/pipeline/data_validation.py", line 13, in initiate_data_validation
    data_validation_config= config.get_data_validation_config()
  File "/Users/neerajbhauryal/Desktop/ML projects/DS-Project/src/DS_Project/config/configuration.py", line 30, in get_data_validation_config
    config = self.config.data_validation
  File "box/config_box.py", line 31, in box.config_box.ConfigBox.__getattr__
  File "box/box.py", line 649, in box.box.Box.__getattr__
box.exceptions.BoxKeyError: "'ConfigBox' object has no attribute 'data_validation'"
[2025-03-03 16:28:38,704: INFO: main: >>>>> stage Data Ingestion Stage started <<<<<<]
[2025-03-03 16:28:38,706: INFO: common: yaml file: config/config.yaml loaded successfully]
[2025-03-03 16:28:38,707: INFO: common: yaml file: params.yaml loaded successfully]
[2025-03-03 16:28:38,708: INFO: common: yaml file: schema.yaml loaded successfully]
[2025-03-03 16:28:38,709: INFO: common: created directory at: artifacts]
[2025-03-03 16:28:38,709: INFO: common: created directory at: artifacts/data_ingestion]
[2025-03-03 16:28:38,709: INFO: data_ingestion: File already exists]
[2025-03-03 16:28:38,711: INFO: main: >>>>>> stage Data Ingestion Stage completed <<<<<

x=======x]
[2025-03-03 16:28:38,711: INFO: main: >>>>> stage Data Validation Stage started <<<<<<]
[2025-03-03 16:28:38,713: INFO: common: yaml file: config/config.yaml loaded successfully]
[2025-03-03 16:28:38,713: INFO: common: yaml file: params.yaml loaded successfully]
[2025-03-03 16:28:38,715: INFO: common: yaml file: schema.yaml loaded successfully]
[2025-03-03 16:28:38,715: INFO: common: created directory at: artifacts]
[2025-03-03 16:28:38,716: ERROR: main: "'ConfigBox' object has no attribute 'data_validation'"]
Traceback (most recent call last):
  File "box/box.py", line 594, in box.box.Box.__getitem__
KeyError: 'data_validation'

The above exception was the direct cause of the following exception:

Traceback (most recent call last):
  File "box/box.py", line 633, in box.box.Box.__getattr__
  File "box/box.py", line 621, in box.box.Box.__getitem__
box.exceptions.BoxKeyError: "'data_validation'"

During handling of the above exception, another exception occurred:

Traceback (most recent call last):
  File "box/box.py", line 635, in box.box.Box.__getattr__
AttributeError: 'ConfigBox' object has no attribute 'data_validation'

The above exception was the direct cause of the following exception:

Traceback (most recent call last):
  File "box/config_box.py", line 29, in box.config_box.ConfigBox.__getattr__
  File "box/box.py", line 649, in box.box.Box.__getattr__
box.exceptions.BoxKeyError: "'ConfigBox' object has no attribute 'data_validation'"

During handling of the above exception, another exception occurred:

Traceback (most recent call last):
  File "box/box.py", line 594, in box.box.Box.__getitem__
KeyError: 'data_validation'

The above exception was the direct cause of the following exception:

Traceback (most recent call last):
  File "box/box.py", line 633, in box.box.Box.__getattr__
  File "box/box.py", line 621, in box.box.Box.__getitem__
box.exceptions.BoxKeyError: "'data_validation'"

During handling of the above exception, another exception occurred:

Traceback (most recent call last):
  File "box/box.py", line 635, in box.box.Box.__getattr__
AttributeError: 'ConfigBox' object has no attribute 'data_validation'

The above exception was the direct cause of the following exception:

Traceback (most recent call last):
  File "/Users/neerajbhauryal/Desktop/ML projects/DS-Project/main.py", line 20, in <module>
    obj.initiate_data_validation()
  File "/Users/neerajbhauryal/Desktop/ML projects/DS-Project/src/DS_Project/pipeline/data_validation.py", line 13, in initiate_data_validation
    data_validation_config= config.get_data_validation_config()
  File "/Users/neerajbhauryal/Desktop/ML projects/DS-Project/src/DS_Project/config/configuration.py", line 30, in get_data_validation_config
    config = self.config.data_validation
  File "box/config_box.py", line 31, in box.config_box.ConfigBox.__getattr__
  File "box/box.py", line 649, in box.box.Box.__getattr__
box.exceptions.BoxKeyError: "'ConfigBox' object has no attribute 'data_validation'"
[2025-03-03 16:34:58,427: INFO: main: >>>>> stage Data Ingestion Stage started <<<<<<]
[2025-03-03 16:34:58,429: INFO: common: yaml file: config/config.yaml loaded successfully]
[2025-03-03 16:34:58,431: INFO: common: yaml file: params.yaml loaded successfully]
[2025-03-03 16:34:58,433: INFO: common: yaml file: schema.yaml loaded successfully]
[2025-03-03 16:34:58,434: INFO: common: created directory at: artifacts]
[2025-03-03 16:34:58,435: INFO: common: created directory at: artifacts/data_ingestion]
[2025-03-03 16:34:58,435: INFO: data_ingestion: File already exists]
[2025-03-03 16:34:58,438: INFO: main: >>>>>> stage Data Ingestion Stage completed <<<<<

x=======x]
[2025-03-03 16:34:58,439: INFO: main: >>>>> stage Data Validation Stage started <<<<<<]
[2025-03-03 16:34:58,441: INFO: common: yaml file: config/config.yaml loaded successfully]
[2025-03-03 16:34:58,442: INFO: common: yaml file: params.yaml loaded successfully]
[2025-03-03 16:34:58,443: INFO: common: yaml file: schema.yaml loaded successfully]
[2025-03-03 16:34:58,443: INFO: common: created directory at: artifacts]
[2025-03-03 16:34:58,443: INFO: common: created directory at: artifacts/data_validation]
[2025-03-03 16:34:58,444: ERROR: main: DataValidationConfig.__init__() got an unexpected keyword argument 'STATUS_FILE']
Traceback (most recent call last):
  File "/Users/neerajbhauryal/Desktop/ML projects/DS-Project/main.py", line 20, in <module>
    obj.initiate_data_validation()
  File "/Users/neerajbhauryal/Desktop/ML projects/DS-Project/src/DS_Project/pipeline/data_validation.py", line 13, in initiate_data_validation
    data_validation_config= config.get_data_validation_config()
  File "/Users/neerajbhauryal/Desktop/ML projects/DS-Project/src/DS_Project/config/configuration.py", line 35, in get_data_validation_config
    data_validation_config = DataValidationConfig(
TypeError: DataValidationConfig.__init__() got an unexpected keyword argument 'STATUS_FILE'
[2025-03-03 16:39:07,611: INFO: main: >>>>> stage Data Ingestion Stage started <<<<<<]
[2025-03-03 16:39:07,613: INFO: common: yaml file: config/config.yaml loaded successfully]
[2025-03-03 16:39:07,615: INFO: common: yaml file: params.yaml loaded successfully]
[2025-03-03 16:39:07,616: INFO: common: yaml file: schema.yaml loaded successfully]
[2025-03-03 16:39:07,617: INFO: common: created directory at: artifacts]
[2025-03-03 16:39:07,617: INFO: common: created directory at: artifacts/data_ingestion]
[2025-03-03 16:39:07,617: INFO: data_ingestion: File already exists]
[2025-03-03 16:39:07,620: INFO: main: >>>>>> stage Data Ingestion Stage completed <<<<<

x=======x]
[2025-03-03 16:39:07,620: INFO: main: >>>>> stage Data Validation Stage started <<<<<<]
[2025-03-03 16:39:07,622: INFO: common: yaml file: config/config.yaml loaded successfully]
[2025-03-03 16:39:07,624: INFO: common: yaml file: params.yaml loaded successfully]
[2025-03-03 16:39:07,626: INFO: common: yaml file: schema.yaml loaded successfully]
[2025-03-03 16:39:07,626: INFO: common: created directory at: artifacts]
[2025-03-03 16:39:07,627: INFO: common: created directory at: artifacts/data_validation]
[2025-03-03 16:39:07,627: ERROR: main: DataValidationConfig.__init__() got an unexpected keyword argument 'unzip_data_dir']
Traceback (most recent call last):
  File "/Users/neerajbhauryal/Desktop/ML projects/DS-Project/main.py", line 20, in <module>
    obj.initiate_data_validation()
  File "/Users/neerajbhauryal/Desktop/ML projects/DS-Project/src/DS_Project/pipeline/data_validation.py", line 13, in initiate_data_validation
    data_validation_config= config.get_data_validation_config()
  File "/Users/neerajbhauryal/Desktop/ML projects/DS-Project/src/DS_Project/config/configuration.py", line 35, in get_data_validation_config
    data_validation_config = DataValidationConfig(
TypeError: DataValidationConfig.__init__() got an unexpected keyword argument 'unzip_data_dir'
[2025-03-03 16:41:34,523: INFO: main: >>>>> stage Data Ingestion Stage started <<<<<<]
[2025-03-03 16:41:34,525: INFO: common: yaml file: config/config.yaml loaded successfully]
[2025-03-03 16:41:34,527: INFO: common: yaml file: params.yaml loaded successfully]
[2025-03-03 16:41:34,529: INFO: common: yaml file: schema.yaml loaded successfully]
[2025-03-03 16:41:34,529: INFO: common: created directory at: artifacts]
[2025-03-03 16:41:34,530: INFO: common: created directory at: artifacts/data_ingestion]
[2025-03-03 16:41:34,530: INFO: data_ingestion: File already exists]
[2025-03-03 16:41:34,533: INFO: main: >>>>>> stage Data Ingestion Stage completed <<<<<

x=======x]
[2025-03-03 16:41:34,533: INFO: main: >>>>> stage Data Validation Stage started <<<<<<]
[2025-03-03 16:41:34,535: INFO: common: yaml file: config/config.yaml loaded successfully]
[2025-03-03 16:41:34,536: INFO: common: yaml file: params.yaml loaded successfully]
[2025-03-03 16:41:34,537: INFO: common: yaml file: schema.yaml loaded successfully]
[2025-03-03 16:41:34,538: INFO: common: created directory at: artifacts]
[2025-03-03 16:41:34,538: INFO: common: created directory at: artifacts/data_validation]
[2025-03-03 16:41:34,538: ERROR: main: 'DataValidation' object has no attribute 'validation_all_columns']
Traceback (most recent call last):
  File "/Users/neerajbhauryal/Desktop/ML projects/DS-Project/main.py", line 20, in <module>
    obj.initiate_data_validation()
  File "/Users/neerajbhauryal/Desktop/ML projects/DS-Project/src/DS_Project/pipeline/data_validation.py", line 15, in initiate_data_validation
    data_validation.validation_all_columns()
AttributeError: 'DataValidation' object has no attribute 'validation_all_columns'
[2025-03-03 16:42:46,674: INFO: main: >>>>> stage Data Ingestion Stage started <<<<<<]
[2025-03-03 16:42:46,675: INFO: common: yaml file: config/config.yaml loaded successfully]
[2025-03-03 16:42:46,676: INFO: common: yaml file: params.yaml loaded successfully]
[2025-03-03 16:42:46,677: INFO: common: yaml file: schema.yaml loaded successfully]
[2025-03-03 16:42:46,678: INFO: common: created directory at: artifacts]
[2025-03-03 16:42:46,678: INFO: common: created directory at: artifacts/data_ingestion]
[2025-03-03 16:42:46,678: INFO: data_ingestion: File already exists]
[2025-03-03 16:42:46,679: INFO: main: >>>>>> stage Data Ingestion Stage completed <<<<<

x=======x]
[2025-03-03 16:42:46,679: INFO: main: >>>>> stage Data Validation Stage started <<<<<<]
[2025-03-03 16:42:46,681: INFO: common: yaml file: config/config.yaml loaded successfully]
[2025-03-03 16:42:46,682: INFO: common: yaml file: params.yaml loaded successfully]
[2025-03-03 16:42:46,684: INFO: common: yaml file: schema.yaml loaded successfully]
[2025-03-03 16:42:46,684: INFO: common: created directory at: artifacts]
[2025-03-03 16:42:46,685: INFO: common: created directory at: artifacts/data_validation]
[2025-03-03 16:42:46,702: INFO: main: >>>>>> stage Data Validation Stage completed <<<<<

x=======x]
