[2025-03-03 11:16:13,040: INFO: main: >>>>> stage Data Ingestion Stage started <<<<<<]
[2025-03-03 11:16:13,042: INFO: common: yaml file: config/config.yaml loaded successfully]
[2025-03-03 11:16:13,042: INFO: common: yaml file: params.yaml loaded successfully]
[2025-03-03 11:16:13,043: ERROR: main: yaml file is empty]
Traceback (most recent call last):
  File "/Users/neerajbhauryal/Desktop/ML projects/DS-Project/src/DS_Project/utils/common.py", line 31, in read_yaml
    return ConfigBox(content)
  File "box/box.py", line 295, in box.box.Box.__init__
box.exceptions.BoxValueError: First argument must be mapping or iterable

During handling of the above exception, another exception occurred:

Traceback (most recent call last):
  File "/Users/neerajbhauryal/Desktop/ML projects/DS-Project/main.py", line 8, in <module>
    obj.initiate_data_ingestion()
  File "/Users/neerajbhauryal/Desktop/ML projects/DS-Project/src/DS_Project/pipeline/data_ingestion.py", line 12, in initiate_data_ingestion
    config=ConfigurationManager()
  File "/Users/neerajbhauryal/Desktop/ML projects/DS-Project/src/DS_Project/config/configuration.py", line 12, in __init__
    self.params = read_yaml(params_filepath)
  File "/Users/neerajbhauryal/Desktop/ML projects/DS-Project/venv/lib/python3.10/site-packages/ensure/main.py", line 872, in __call__
    return_val = self.f(*args, **kwargs)
  File "/Users/neerajbhauryal/Desktop/ML projects/DS-Project/src/DS_Project/utils/common.py", line 33, in read_yaml
    raise ValueError("yaml file is empty")
ValueError: yaml file is empty
[2025-03-03 11:17:37,938: INFO: main: >>>>> stage Data Ingestion Stage started <<<<<<]
[2025-03-03 11:17:37,940: INFO: common: yaml file: config/config.yaml loaded successfully]
[2025-03-03 11:17:37,940: INFO: common: yaml file: params.yaml loaded successfully]
[2025-03-03 11:17:37,941: INFO: common: yaml file: schema.yaml loaded successfully]
[2025-03-03 11:17:37,941: INFO: common: created directory at: artifacts]
[2025-03-03 11:17:37,941: INFO: common: created directory at: artifacts/data_ingestion]
[2025-03-03 11:17:38,443: INFO: data_ingestion: artifacts/data_ingestion/data.zip download! with following info: 
Connection: close
Content-Length: 23329
Cache-Control: max-age=300
Content-Security-Policy: default-src 'none'; style-src 'unsafe-inline'; sandbox
Content-Type: application/zip
ETag: "c69888a4ae59bc5a893392785a938ccd4937981c06ba8a9d6a21aa52b4ab5b6e"
Strict-Transport-Security: max-age=31536000
X-Content-Type-Options: nosniff
X-Frame-Options: deny
X-XSS-Protection: 1; mode=block
X-GitHub-Request-Id: 22C2:1D364:C8D1F9:E711DF:67C581C1
Accept-Ranges: bytes
Date: Mon, 03 Mar 2025 10:17:38 GMT
Via: 1.1 varnish
X-Served-By: cache-fra-eddf8230151-FRA
X-Cache: MISS
X-Cache-Hits: 0
X-Timer: S1740997058.271546,VS0,VE157
Vary: Authorization,Accept-Encoding,Origin
Access-Control-Allow-Origin: *
Cross-Origin-Resource-Policy: cross-origin
X-Fastly-Request-ID: ae6d4df3ab71e8be1ee8f7c22f8f588e5dd0cd1f
Expires: Mon, 03 Mar 2025 10:22:38 GMT
Source-Age: 0

]
[2025-03-03 11:17:38,449: INFO: main: >>>>>> stage Data Ingestion Stage completed <<<<<

x=======x]
[2025-03-03 16:22:27,822: INFO: main: >>>>> stage Data Ingestion Stage started <<<<<<]
[2025-03-03 16:22:27,824: INFO: common: yaml file: config/config.yaml loaded successfully]
[2025-03-03 16:22:27,826: INFO: common: yaml file: params.yaml loaded successfully]
[2025-03-03 16:22:27,828: INFO: common: yaml file: schema.yaml loaded successfully]
[2025-03-03 16:22:27,829: INFO: common: created directory at: artifacts]
[2025-03-03 16:22:27,829: INFO: common: created directory at: artifacts/data_ingestion]
[2025-03-03 16:22:27,829: INFO: data_ingestion: File already exists]
[2025-03-03 16:22:27,834: INFO: main: >>>>>> stage Data Ingestion Stage completed <<<<<

x=======x]
[2025-03-03 16:22:27,834: INFO: main: >>>>> stage Data Validation Stage started <<<<<<]
[2025-03-03 16:22:27,834: ERROR: main: 'DataValidationTrainingPipeline' object has no attribute 'initiate_data_ingestion']
Traceback (most recent call last):
  File "/Users/neerajbhauryal/Desktop/ML projects/DS-Project/main.py", line 20, in <module>
    obj.initiate_data_ingestion()
AttributeError: 'DataValidationTrainingPipeline' object has no attribute 'initiate_data_ingestion'
[2025-03-03 16:23:48,050: INFO: main: >>>>> stage Data Ingestion Stage started <<<<<<]
[2025-03-03 16:23:48,052: INFO: common: yaml file: config/config.yaml loaded successfully]
[2025-03-03 16:23:48,052: INFO: common: yaml file: params.yaml loaded successfully]
[2025-03-03 16:23:48,054: INFO: common: yaml file: schema.yaml loaded successfully]
[2025-03-03 16:23:48,054: INFO: common: created directory at: artifacts]
[2025-03-03 16:23:48,054: INFO: common: created directory at: artifacts/data_ingestion]
[2025-03-03 16:23:48,054: INFO: data_ingestion: File already exists]
[2025-03-03 16:23:48,056: INFO: main: >>>>>> stage Data Ingestion Stage completed <<<<<

x=======x]
[2025-03-03 16:23:48,056: INFO: main: >>>>> stage Data Validation Stage started <<<<<<]
[2025-03-03 16:23:48,058: INFO: common: yaml file: config/config.yaml loaded successfully]
[2025-03-03 16:23:48,059: INFO: common: yaml file: params.yaml loaded successfully]
[2025-03-03 16:23:48,060: INFO: common: yaml file: schema.yaml loaded successfully]
[2025-03-03 16:23:48,061: INFO: common: created directory at: artifacts]
[2025-03-03 16:23:48,061: ERROR: main: "'ConfigBox' object has no attribute 'data_validation'"]
Traceback (most recent call last):
  File "box/box.py", line 594, in box.box.Box.__getitem__
KeyError: 'data_validation'

The above exception was the direct cause of the following exception:

Traceback (most recent call last):
  File "box/box.py", line 633, in box.box.Box.__getattr__
  File "box/box.py", line 621, in box.box.Box.__getitem__
box.exceptions.BoxKeyError: "'data_validation'"

During handling of the above exception, another exception occurred:

Traceback (most recent call last):
  File "box/box.py", line 635, in box.box.Box.__getattr__
AttributeError: 'ConfigBox' object has no attribute 'data_validation'

The above exception was the direct cause of the following exception:

Traceback (most recent call last):
  File "box/config_box.py", line 29, in box.config_box.ConfigBox.__getattr__
  File "box/box.py", line 649, in box.box.Box.__getattr__
box.exceptions.BoxKeyError: "'ConfigBox' object has no attribute 'data_validation'"

During handling of the above exception, another exception occurred:

Traceback (most recent call last):
  File "box/box.py", line 594, in box.box.Box.__getitem__
KeyError: 'data_validation'

The above exception was the direct cause of the following exception:

Traceback (most recent call last):
  File "box/box.py", line 633, in box.box.Box.__getattr__
  File "box/box.py", line 621, in box.box.Box.__getitem__
box.exceptions.BoxKeyError: "'data_validation'"

During handling of the above exception, another exception occurred:

Traceback (most recent call last):
  File "box/box.py", line 635, in box.box.Box.__getattr__
AttributeError: 'ConfigBox' object has no attribute 'data_validation'

The above exception was the direct cause of the following exception:

Traceback (most recent call last):
  File "/Users/neerajbhauryal/Desktop/ML projects/DS-Project/main.py", line 20, in <module>
    obj.initiate_data_validation()
  File "/Users/neerajbhauryal/Desktop/ML projects/DS-Project/src/DS_Project/pipeline/data_validation.py", line 13, in initiate_data_validation
    data_validation_config= config.get_data_validation_config()
  File "/Users/neerajbhauryal/Desktop/ML projects/DS-Project/src/DS_Project/config/configuration.py", line 30, in get_data_validation_config
    config = self.config.data_validation
  File "box/config_box.py", line 31, in box.config_box.ConfigBox.__getattr__
  File "box/box.py", line 649, in box.box.Box.__getattr__
box.exceptions.BoxKeyError: "'ConfigBox' object has no attribute 'data_validation'"
[2025-03-03 16:28:38,704: INFO: main: >>>>> stage Data Ingestion Stage started <<<<<<]
[2025-03-03 16:28:38,706: INFO: common: yaml file: config/config.yaml loaded successfully]
[2025-03-03 16:28:38,707: INFO: common: yaml file: params.yaml loaded successfully]
[2025-03-03 16:28:38,708: INFO: common: yaml file: schema.yaml loaded successfully]
[2025-03-03 16:28:38,709: INFO: common: created directory at: artifacts]
[2025-03-03 16:28:38,709: INFO: common: created directory at: artifacts/data_ingestion]
[2025-03-03 16:28:38,709: INFO: data_ingestion: File already exists]
[2025-03-03 16:28:38,711: INFO: main: >>>>>> stage Data Ingestion Stage completed <<<<<

x=======x]
[2025-03-03 16:28:38,711: INFO: main: >>>>> stage Data Validation Stage started <<<<<<]
[2025-03-03 16:28:38,713: INFO: common: yaml file: config/config.yaml loaded successfully]
[2025-03-03 16:28:38,713: INFO: common: yaml file: params.yaml loaded successfully]
[2025-03-03 16:28:38,715: INFO: common: yaml file: schema.yaml loaded successfully]
[2025-03-03 16:28:38,715: INFO: common: created directory at: artifacts]
[2025-03-03 16:28:38,716: ERROR: main: "'ConfigBox' object has no attribute 'data_validation'"]
Traceback (most recent call last):
  File "box/box.py", line 594, in box.box.Box.__getitem__
KeyError: 'data_validation'

The above exception was the direct cause of the following exception:

Traceback (most recent call last):
  File "box/box.py", line 633, in box.box.Box.__getattr__
  File "box/box.py", line 621, in box.box.Box.__getitem__
box.exceptions.BoxKeyError: "'data_validation'"

During handling of the above exception, another exception occurred:

Traceback (most recent call last):
  File "box/box.py", line 635, in box.box.Box.__getattr__
AttributeError: 'ConfigBox' object has no attribute 'data_validation'

The above exception was the direct cause of the following exception:

Traceback (most recent call last):
  File "box/config_box.py", line 29, in box.config_box.ConfigBox.__getattr__
  File "box/box.py", line 649, in box.box.Box.__getattr__
box.exceptions.BoxKeyError: "'ConfigBox' object has no attribute 'data_validation'"

During handling of the above exception, another exception occurred:

Traceback (most recent call last):
  File "box/box.py", line 594, in box.box.Box.__getitem__
KeyError: 'data_validation'

The above exception was the direct cause of the following exception:

Traceback (most recent call last):
  File "box/box.py", line 633, in box.box.Box.__getattr__
  File "box/box.py", line 621, in box.box.Box.__getitem__
box.exceptions.BoxKeyError: "'data_validation'"

During handling of the above exception, another exception occurred:

Traceback (most recent call last):
  File "box/box.py", line 635, in box.box.Box.__getattr__
AttributeError: 'ConfigBox' object has no attribute 'data_validation'

The above exception was the direct cause of the following exception:

Traceback (most recent call last):
  File "/Users/neerajbhauryal/Desktop/ML projects/DS-Project/main.py", line 20, in <module>
    obj.initiate_data_validation()
  File "/Users/neerajbhauryal/Desktop/ML projects/DS-Project/src/DS_Project/pipeline/data_validation.py", line 13, in initiate_data_validation
    data_validation_config= config.get_data_validation_config()
  File "/Users/neerajbhauryal/Desktop/ML projects/DS-Project/src/DS_Project/config/configuration.py", line 30, in get_data_validation_config
    config = self.config.data_validation
  File "box/config_box.py", line 31, in box.config_box.ConfigBox.__getattr__
  File "box/box.py", line 649, in box.box.Box.__getattr__
box.exceptions.BoxKeyError: "'ConfigBox' object has no attribute 'data_validation'"
[2025-03-03 16:34:58,427: INFO: main: >>>>> stage Data Ingestion Stage started <<<<<<]
[2025-03-03 16:34:58,429: INFO: common: yaml file: config/config.yaml loaded successfully]
[2025-03-03 16:34:58,431: INFO: common: yaml file: params.yaml loaded successfully]
[2025-03-03 16:34:58,433: INFO: common: yaml file: schema.yaml loaded successfully]
[2025-03-03 16:34:58,434: INFO: common: created directory at: artifacts]
[2025-03-03 16:34:58,435: INFO: common: created directory at: artifacts/data_ingestion]
[2025-03-03 16:34:58,435: INFO: data_ingestion: File already exists]
[2025-03-03 16:34:58,438: INFO: main: >>>>>> stage Data Ingestion Stage completed <<<<<

x=======x]
[2025-03-03 16:34:58,439: INFO: main: >>>>> stage Data Validation Stage started <<<<<<]
[2025-03-03 16:34:58,441: INFO: common: yaml file: config/config.yaml loaded successfully]
[2025-03-03 16:34:58,442: INFO: common: yaml file: params.yaml loaded successfully]
[2025-03-03 16:34:58,443: INFO: common: yaml file: schema.yaml loaded successfully]
[2025-03-03 16:34:58,443: INFO: common: created directory at: artifacts]
[2025-03-03 16:34:58,443: INFO: common: created directory at: artifacts/data_validation]
[2025-03-03 16:34:58,444: ERROR: main: DataValidationConfig.__init__() got an unexpected keyword argument 'STATUS_FILE']
Traceback (most recent call last):
  File "/Users/neerajbhauryal/Desktop/ML projects/DS-Project/main.py", line 20, in <module>
    obj.initiate_data_validation()
  File "/Users/neerajbhauryal/Desktop/ML projects/DS-Project/src/DS_Project/pipeline/data_validation.py", line 13, in initiate_data_validation
    data_validation_config= config.get_data_validation_config()
  File "/Users/neerajbhauryal/Desktop/ML projects/DS-Project/src/DS_Project/config/configuration.py", line 35, in get_data_validation_config
    data_validation_config = DataValidationConfig(
TypeError: DataValidationConfig.__init__() got an unexpected keyword argument 'STATUS_FILE'
[2025-03-03 16:39:07,611: INFO: main: >>>>> stage Data Ingestion Stage started <<<<<<]
[2025-03-03 16:39:07,613: INFO: common: yaml file: config/config.yaml loaded successfully]
[2025-03-03 16:39:07,615: INFO: common: yaml file: params.yaml loaded successfully]
[2025-03-03 16:39:07,616: INFO: common: yaml file: schema.yaml loaded successfully]
[2025-03-03 16:39:07,617: INFO: common: created directory at: artifacts]
[2025-03-03 16:39:07,617: INFO: common: created directory at: artifacts/data_ingestion]
[2025-03-03 16:39:07,617: INFO: data_ingestion: File already exists]
[2025-03-03 16:39:07,620: INFO: main: >>>>>> stage Data Ingestion Stage completed <<<<<

x=======x]
[2025-03-03 16:39:07,620: INFO: main: >>>>> stage Data Validation Stage started <<<<<<]
[2025-03-03 16:39:07,622: INFO: common: yaml file: config/config.yaml loaded successfully]
[2025-03-03 16:39:07,624: INFO: common: yaml file: params.yaml loaded successfully]
[2025-03-03 16:39:07,626: INFO: common: yaml file: schema.yaml loaded successfully]
[2025-03-03 16:39:07,626: INFO: common: created directory at: artifacts]
[2025-03-03 16:39:07,627: INFO: common: created directory at: artifacts/data_validation]
[2025-03-03 16:39:07,627: ERROR: main: DataValidationConfig.__init__() got an unexpected keyword argument 'unzip_data_dir']
Traceback (most recent call last):
  File "/Users/neerajbhauryal/Desktop/ML projects/DS-Project/main.py", line 20, in <module>
    obj.initiate_data_validation()
  File "/Users/neerajbhauryal/Desktop/ML projects/DS-Project/src/DS_Project/pipeline/data_validation.py", line 13, in initiate_data_validation
    data_validation_config= config.get_data_validation_config()
  File "/Users/neerajbhauryal/Desktop/ML projects/DS-Project/src/DS_Project/config/configuration.py", line 35, in get_data_validation_config
    data_validation_config = DataValidationConfig(
TypeError: DataValidationConfig.__init__() got an unexpected keyword argument 'unzip_data_dir'
[2025-03-03 16:41:34,523: INFO: main: >>>>> stage Data Ingestion Stage started <<<<<<]
[2025-03-03 16:41:34,525: INFO: common: yaml file: config/config.yaml loaded successfully]
[2025-03-03 16:41:34,527: INFO: common: yaml file: params.yaml loaded successfully]
[2025-03-03 16:41:34,529: INFO: common: yaml file: schema.yaml loaded successfully]
[2025-03-03 16:41:34,529: INFO: common: created directory at: artifacts]
[2025-03-03 16:41:34,530: INFO: common: created directory at: artifacts/data_ingestion]
[2025-03-03 16:41:34,530: INFO: data_ingestion: File already exists]
[2025-03-03 16:41:34,533: INFO: main: >>>>>> stage Data Ingestion Stage completed <<<<<

x=======x]
[2025-03-03 16:41:34,533: INFO: main: >>>>> stage Data Validation Stage started <<<<<<]
[2025-03-03 16:41:34,535: INFO: common: yaml file: config/config.yaml loaded successfully]
[2025-03-03 16:41:34,536: INFO: common: yaml file: params.yaml loaded successfully]
[2025-03-03 16:41:34,537: INFO: common: yaml file: schema.yaml loaded successfully]
[2025-03-03 16:41:34,538: INFO: common: created directory at: artifacts]
[2025-03-03 16:41:34,538: INFO: common: created directory at: artifacts/data_validation]
[2025-03-03 16:41:34,538: ERROR: main: 'DataValidation' object has no attribute 'validation_all_columns']
Traceback (most recent call last):
  File "/Users/neerajbhauryal/Desktop/ML projects/DS-Project/main.py", line 20, in <module>
    obj.initiate_data_validation()
  File "/Users/neerajbhauryal/Desktop/ML projects/DS-Project/src/DS_Project/pipeline/data_validation.py", line 15, in initiate_data_validation
    data_validation.validation_all_columns()
AttributeError: 'DataValidation' object has no attribute 'validation_all_columns'
[2025-03-03 16:42:46,674: INFO: main: >>>>> stage Data Ingestion Stage started <<<<<<]
[2025-03-03 16:42:46,675: INFO: common: yaml file: config/config.yaml loaded successfully]
[2025-03-03 16:42:46,676: INFO: common: yaml file: params.yaml loaded successfully]
[2025-03-03 16:42:46,677: INFO: common: yaml file: schema.yaml loaded successfully]
[2025-03-03 16:42:46,678: INFO: common: created directory at: artifacts]
[2025-03-03 16:42:46,678: INFO: common: created directory at: artifacts/data_ingestion]
[2025-03-03 16:42:46,678: INFO: data_ingestion: File already exists]
[2025-03-03 16:42:46,679: INFO: main: >>>>>> stage Data Ingestion Stage completed <<<<<

x=======x]
[2025-03-03 16:42:46,679: INFO: main: >>>>> stage Data Validation Stage started <<<<<<]
[2025-03-03 16:42:46,681: INFO: common: yaml file: config/config.yaml loaded successfully]
[2025-03-03 16:42:46,682: INFO: common: yaml file: params.yaml loaded successfully]
[2025-03-03 16:42:46,684: INFO: common: yaml file: schema.yaml loaded successfully]
[2025-03-03 16:42:46,684: INFO: common: created directory at: artifacts]
[2025-03-03 16:42:46,685: INFO: common: created directory at: artifacts/data_validation]
[2025-03-03 16:42:46,702: INFO: main: >>>>>> stage Data Validation Stage completed <<<<<

x=======x]
[2025-03-03 20:47:08,519: INFO: main: >>>>> stage Data Ingestion Stage started <<<<<<]
[2025-03-03 20:47:08,525: INFO: common: yaml file: config/config.yaml loaded successfully]
[2025-03-03 20:47:08,529: INFO: common: yaml file: params.yaml loaded successfully]
[2025-03-03 20:47:08,533: INFO: common: yaml file: schema.yaml loaded successfully]
[2025-03-03 20:47:08,535: INFO: common: created directory at: artifacts]
[2025-03-03 20:47:08,535: INFO: common: created directory at: artifacts/data_ingestion]
[2025-03-03 20:47:08,536: INFO: data_ingestion: File already exists]
[2025-03-03 20:47:08,546: INFO: main: >>>>>> stage Data Ingestion Stage completed <<<<<

x=======x]
[2025-03-03 20:47:08,546: INFO: main: >>>>> stage Data Validation Stage started <<<<<<]
[2025-03-03 20:47:08,548: INFO: common: yaml file: config/config.yaml loaded successfully]
[2025-03-03 20:47:08,548: INFO: common: yaml file: params.yaml loaded successfully]
[2025-03-03 20:47:08,550: INFO: common: yaml file: schema.yaml loaded successfully]
[2025-03-03 20:47:08,551: INFO: common: created directory at: artifacts]
[2025-03-03 20:47:08,551: INFO: common: created directory at: artifacts/data_validation]
[2025-03-03 20:47:08,571: INFO: main: >>>>>> stage Data Validation Stage completed <<<<<

x=======x]
[2025-03-03 20:47:08,571: INFO: main: >>>>> stage Data Transformation Stage started <<<<<<]
[2025-03-03 20:47:08,571: ERROR: main: 'DataTransformationTrainingPipeline' object has no attribute 'initiate_data_validation']
Traceback (most recent call last):
  File "/Users/neerajbhauryal/Desktop/ML projects/DS-Project/main.py", line 32, in <module>
    obj.initiate_data_validation()
AttributeError: 'DataTransformationTrainingPipeline' object has no attribute 'initiate_data_validation'
[2025-03-03 20:47:33,092: INFO: main: >>>>> stage Data Ingestion Stage started <<<<<<]
[2025-03-03 20:47:33,093: INFO: common: yaml file: config/config.yaml loaded successfully]
[2025-03-03 20:47:33,094: INFO: common: yaml file: params.yaml loaded successfully]
[2025-03-03 20:47:33,096: INFO: common: yaml file: schema.yaml loaded successfully]
[2025-03-03 20:47:33,096: INFO: common: created directory at: artifacts]
[2025-03-03 20:47:33,096: INFO: common: created directory at: artifacts/data_ingestion]
[2025-03-03 20:47:33,096: INFO: data_ingestion: File already exists]
[2025-03-03 20:47:33,098: INFO: main: >>>>>> stage Data Ingestion Stage completed <<<<<

x=======x]
[2025-03-03 20:47:33,098: INFO: main: >>>>> stage Data Validation Stage started <<<<<<]
[2025-03-03 20:47:33,100: INFO: common: yaml file: config/config.yaml loaded successfully]
[2025-03-03 20:47:33,101: INFO: common: yaml file: params.yaml loaded successfully]
[2025-03-03 20:47:33,103: INFO: common: yaml file: schema.yaml loaded successfully]
[2025-03-03 20:47:33,103: INFO: common: created directory at: artifacts]
[2025-03-03 20:47:33,103: INFO: common: created directory at: artifacts/data_validation]
[2025-03-03 20:47:33,112: INFO: main: >>>>>> stage Data Validation Stage completed <<<<<

x=======x]
[2025-03-03 20:47:33,112: INFO: main: >>>>> stage Data Transformation Stage started <<<<<<]
[2025-03-03 20:47:33,114: INFO: common: yaml file: config/config.yaml loaded successfully]
[2025-03-03 20:47:33,114: INFO: common: yaml file: params.yaml loaded successfully]
[2025-03-03 20:47:33,116: INFO: common: yaml file: schema.yaml loaded successfully]
[2025-03-03 20:47:33,116: INFO: common: created directory at: artifacts]
[2025-03-03 20:47:33,116: INFO: common: created directory at: artifacts/data_transformation]
[2025-03-03 20:47:33,149: INFO: data_transformation: Splited data into training and test sets]
[2025-03-03 20:47:33,149: INFO: data_transformation: (1199, 12)]
[2025-03-03 20:47:33,149: INFO: data_transformation: (400, 12)]
[2025-03-03 20:47:33,149: INFO: main: >>>>>> stage Data Transformation Stage completed <<<<<

x=======x]
[2025-03-04 15:39:08,174: INFO: main: >>>>> stage Data Ingestion Stage started <<<<<<]
[2025-03-04 15:39:08,184: INFO: common: yaml file: config/config.yaml loaded successfully]
[2025-03-04 15:39:08,190: INFO: common: yaml file: params.yaml loaded successfully]
[2025-03-04 15:39:08,196: INFO: common: yaml file: schema.yaml loaded successfully]
[2025-03-04 15:39:08,197: INFO: common: created directory at: artifacts]
[2025-03-04 15:39:08,197: INFO: common: created directory at: artifacts/data_ingestion]
[2025-03-04 15:39:08,197: INFO: data_ingestion: File already exists]
[2025-03-04 15:39:08,204: INFO: main: >>>>>> stage Data Ingestion Stage completed <<<<<

x=======x]
[2025-03-04 15:39:08,204: INFO: main: >>>>> stage Data Validation Stage started <<<<<<]
[2025-03-04 15:39:08,209: INFO: common: yaml file: config/config.yaml loaded successfully]
[2025-03-04 15:39:08,210: INFO: common: yaml file: params.yaml loaded successfully]
[2025-03-04 15:39:08,214: INFO: common: yaml file: schema.yaml loaded successfully]
[2025-03-04 15:39:08,215: INFO: common: created directory at: artifacts]
[2025-03-04 15:39:08,215: INFO: common: created directory at: artifacts/data_validation]
[2025-03-04 15:39:08,230: INFO: main: >>>>>> stage Data Validation Stage completed <<<<<

x=======x]
[2025-03-04 15:39:08,230: INFO: main: >>>>> stage Data Transformation Stage started <<<<<<]
[2025-03-04 15:39:08,234: INFO: common: yaml file: config/config.yaml loaded successfully]
[2025-03-04 15:39:08,235: INFO: common: yaml file: params.yaml loaded successfully]
[2025-03-04 15:39:08,237: INFO: common: yaml file: schema.yaml loaded successfully]
[2025-03-04 15:39:08,237: INFO: common: created directory at: artifacts]
[2025-03-04 15:39:08,237: INFO: common: created directory at: artifacts/data_transformation]
[2025-03-04 15:39:08,267: INFO: data_transformation: Splited data into training and test sets]
[2025-03-04 15:39:08,267: INFO: data_transformation: (1199, 12)]
[2025-03-04 15:39:08,267: INFO: data_transformation: (400, 12)]
[2025-03-04 15:39:08,268: INFO: main: >>>>>> stage Data Transformation Stage completed <<<<<

x=======x]
[2025-03-04 15:39:08,268: INFO: main: >>>>> stage Model Training Stage started <<<<<<]
[2025-03-04 15:39:08,268: ERROR: main: 'ModelTrainingPipeline' object has no attribute 'initiate_data_transformation']
Traceback (most recent call last):
  File "/Users/neerajbhauryal/Desktop/ML projects/DS-Project/main.py", line 43, in <module>
    obj.initiate_data_transformation()
AttributeError: 'ModelTrainingPipeline' object has no attribute 'initiate_data_transformation'
[2025-03-04 15:40:07,660: INFO: main: >>>>> stage Data Ingestion Stage started <<<<<<]
[2025-03-04 15:40:07,662: INFO: common: yaml file: config/config.yaml loaded successfully]
[2025-03-04 15:40:07,663: INFO: common: yaml file: params.yaml loaded successfully]
[2025-03-04 15:40:07,664: INFO: common: yaml file: schema.yaml loaded successfully]
[2025-03-04 15:40:07,665: INFO: common: created directory at: artifacts]
[2025-03-04 15:40:07,665: INFO: common: created directory at: artifacts/data_ingestion]
[2025-03-04 15:40:07,665: INFO: data_ingestion: File already exists]
[2025-03-04 15:40:07,667: INFO: main: >>>>>> stage Data Ingestion Stage completed <<<<<

x=======x]
[2025-03-04 15:40:07,667: INFO: main: >>>>> stage Data Validation Stage started <<<<<<]
[2025-03-04 15:40:07,669: INFO: common: yaml file: config/config.yaml loaded successfully]
[2025-03-04 15:40:07,670: INFO: common: yaml file: params.yaml loaded successfully]
[2025-03-04 15:40:07,671: INFO: common: yaml file: schema.yaml loaded successfully]
[2025-03-04 15:40:07,672: INFO: common: created directory at: artifacts]
[2025-03-04 15:40:07,672: INFO: common: created directory at: artifacts/data_validation]
[2025-03-04 15:40:07,681: INFO: main: >>>>>> stage Data Validation Stage completed <<<<<

x=======x]
[2025-03-04 15:40:07,681: INFO: main: >>>>> stage Data Transformation Stage started <<<<<<]
[2025-03-04 15:40:07,683: INFO: common: yaml file: config/config.yaml loaded successfully]
[2025-03-04 15:40:07,684: INFO: common: yaml file: params.yaml loaded successfully]
[2025-03-04 15:40:07,685: INFO: common: yaml file: schema.yaml loaded successfully]
[2025-03-04 15:40:07,685: INFO: common: created directory at: artifacts]
[2025-03-04 15:40:07,685: INFO: common: created directory at: artifacts/data_transformation]
[2025-03-04 15:40:07,704: INFO: data_transformation: Splited data into training and test sets]
[2025-03-04 15:40:07,704: INFO: data_transformation: (1199, 12)]
[2025-03-04 15:40:07,704: INFO: data_transformation: (400, 12)]
[2025-03-04 15:40:07,704: INFO: main: >>>>>> stage Data Transformation Stage completed <<<<<

x=======x]
[2025-03-04 15:40:07,704: INFO: main: >>>>> stage Model Training Stage started <<<<<<]
[2025-03-04 15:40:07,707: INFO: common: yaml file: config/config.yaml loaded successfully]
[2025-03-04 15:40:07,708: INFO: common: yaml file: params.yaml loaded successfully]
[2025-03-04 15:40:07,710: INFO: common: yaml file: schema.yaml loaded successfully]
[2025-03-04 15:40:07,711: INFO: common: created directory at: artifacts]
[2025-03-04 15:40:07,712: INFO: common: created directory at: artifacts/model_trainer]
[2025-03-04 15:40:07,712: ERROR: main: [Errno 2] No such file or directory: 'artifacts/data_transforamtion/train.csv']
Traceback (most recent call last):
  File "/Users/neerajbhauryal/Desktop/ML projects/DS-Project/main.py", line 43, in <module>
    obj.initiate_model_training()
  File "/Users/neerajbhauryal/Desktop/ML projects/DS-Project/src/DS_Project/pipeline/model_trainer.py", line 15, in initiate_model_training
    model_trainer_config.train()
  File "/Users/neerajbhauryal/Desktop/ML projects/DS-Project/src/DS_Project/components/model_trainer.py", line 14, in train
    train_data = pd.read_csv(self.config.train_data_path)
  File "/Users/neerajbhauryal/Desktop/ML projects/DS-Project/venv/lib/python3.10/site-packages/pandas/io/parsers/readers.py", line 1026, in read_csv
    return _read(filepath_or_buffer, kwds)
  File "/Users/neerajbhauryal/Desktop/ML projects/DS-Project/venv/lib/python3.10/site-packages/pandas/io/parsers/readers.py", line 620, in _read
    parser = TextFileReader(filepath_or_buffer, **kwds)
  File "/Users/neerajbhauryal/Desktop/ML projects/DS-Project/venv/lib/python3.10/site-packages/pandas/io/parsers/readers.py", line 1620, in __init__
    self._engine = self._make_engine(f, self.engine)
  File "/Users/neerajbhauryal/Desktop/ML projects/DS-Project/venv/lib/python3.10/site-packages/pandas/io/parsers/readers.py", line 1880, in _make_engine
    self.handles = get_handle(
  File "/Users/neerajbhauryal/Desktop/ML projects/DS-Project/venv/lib/python3.10/site-packages/pandas/io/common.py", line 873, in get_handle
    handle = open(
FileNotFoundError: [Errno 2] No such file or directory: 'artifacts/data_transforamtion/train.csv'
[2025-03-04 15:41:15,656: INFO: main: >>>>> stage Data Ingestion Stage started <<<<<<]
[2025-03-04 15:41:15,659: INFO: common: yaml file: config/config.yaml loaded successfully]
[2025-03-04 15:41:15,660: INFO: common: yaml file: params.yaml loaded successfully]
[2025-03-04 15:41:15,661: INFO: common: yaml file: schema.yaml loaded successfully]
[2025-03-04 15:41:15,662: INFO: common: created directory at: artifacts]
[2025-03-04 15:41:15,662: INFO: common: created directory at: artifacts/data_ingestion]
[2025-03-04 15:41:15,662: INFO: data_ingestion: File already exists]
[2025-03-04 15:41:15,664: INFO: main: >>>>>> stage Data Ingestion Stage completed <<<<<

x=======x]
[2025-03-04 15:41:15,664: INFO: main: >>>>> stage Data Validation Stage started <<<<<<]
[2025-03-04 15:41:15,666: INFO: common: yaml file: config/config.yaml loaded successfully]
[2025-03-04 15:41:15,668: INFO: common: yaml file: params.yaml loaded successfully]
[2025-03-04 15:41:15,669: INFO: common: yaml file: schema.yaml loaded successfully]
[2025-03-04 15:41:15,670: INFO: common: created directory at: artifacts]
[2025-03-04 15:41:15,670: INFO: common: created directory at: artifacts/data_validation]
[2025-03-04 15:41:15,678: INFO: main: >>>>>> stage Data Validation Stage completed <<<<<

x=======x]
[2025-03-04 15:41:15,678: INFO: main: >>>>> stage Data Transformation Stage started <<<<<<]
[2025-03-04 15:41:15,680: INFO: common: yaml file: config/config.yaml loaded successfully]
[2025-03-04 15:41:15,681: INFO: common: yaml file: params.yaml loaded successfully]
[2025-03-04 15:41:15,682: INFO: common: yaml file: schema.yaml loaded successfully]
[2025-03-04 15:41:15,683: INFO: common: created directory at: artifacts]
[2025-03-04 15:41:15,683: INFO: common: created directory at: artifacts/data_transformation]
[2025-03-04 15:41:15,702: INFO: data_transformation: Splited data into training and test sets]
[2025-03-04 15:41:15,702: INFO: data_transformation: (1199, 12)]
[2025-03-04 15:41:15,702: INFO: data_transformation: (400, 12)]
[2025-03-04 15:41:15,703: INFO: main: >>>>>> stage Data Transformation Stage completed <<<<<

x=======x]
[2025-03-04 15:41:15,703: INFO: main: >>>>> stage Model Training Stage started <<<<<<]
[2025-03-04 15:41:15,705: INFO: common: yaml file: config/config.yaml loaded successfully]
[2025-03-04 15:41:15,706: INFO: common: yaml file: params.yaml loaded successfully]
[2025-03-04 15:41:15,708: INFO: common: yaml file: schema.yaml loaded successfully]
[2025-03-04 15:41:15,708: INFO: common: created directory at: artifacts]
[2025-03-04 15:41:15,708: INFO: common: created directory at: artifacts/model_trainer]
[2025-03-04 15:41:15,716: ERROR: main: 'DataFrame' object is not callable]
Traceback (most recent call last):
  File "/Users/neerajbhauryal/Desktop/ML projects/DS-Project/main.py", line 43, in <module>
    obj.initiate_model_training()
  File "/Users/neerajbhauryal/Desktop/ML projects/DS-Project/src/DS_Project/pipeline/model_trainer.py", line 15, in initiate_model_training
    model_trainer_config.train()
  File "/Users/neerajbhauryal/Desktop/ML projects/DS-Project/src/DS_Project/components/model_trainer.py", line 19, in train
    train_y = train_data([self.config.target_column])
TypeError: 'DataFrame' object is not callable
[2025-03-04 15:59:31,946: INFO: main: >>>>> stage Data Ingestion Stage started <<<<<<]
[2025-03-04 15:59:31,948: INFO: common: yaml file: config/config.yaml loaded successfully]
[2025-03-04 15:59:31,950: INFO: common: yaml file: params.yaml loaded successfully]
[2025-03-04 15:59:31,952: INFO: common: yaml file: schema.yaml loaded successfully]
[2025-03-04 15:59:31,952: INFO: common: created directory at: artifacts]
[2025-03-04 15:59:31,953: INFO: common: created directory at: artifacts/data_ingestion]
[2025-03-04 15:59:31,953: INFO: data_ingestion: File already exists]
[2025-03-04 15:59:31,954: INFO: main: >>>>>> stage Data Ingestion Stage completed <<<<<

x=======x]
[2025-03-04 15:59:31,954: INFO: main: >>>>> stage Data Validation Stage started <<<<<<]
[2025-03-04 15:59:31,956: INFO: common: yaml file: config/config.yaml loaded successfully]
[2025-03-04 15:59:31,957: INFO: common: yaml file: params.yaml loaded successfully]
[2025-03-04 15:59:31,959: INFO: common: yaml file: schema.yaml loaded successfully]
[2025-03-04 15:59:31,959: INFO: common: created directory at: artifacts]
[2025-03-04 15:59:31,959: INFO: common: created directory at: artifacts/data_validation]
[2025-03-04 15:59:31,967: INFO: main: >>>>>> stage Data Validation Stage completed <<<<<

x=======x]
[2025-03-04 15:59:31,967: INFO: main: >>>>> stage Data Transformation Stage started <<<<<<]
[2025-03-04 15:59:31,969: INFO: common: yaml file: config/config.yaml loaded successfully]
[2025-03-04 15:59:31,970: INFO: common: yaml file: params.yaml loaded successfully]
[2025-03-04 15:59:31,971: INFO: common: yaml file: schema.yaml loaded successfully]
[2025-03-04 15:59:31,971: INFO: common: created directory at: artifacts]
[2025-03-04 15:59:31,972: INFO: common: created directory at: artifacts/data_transformation]
[2025-03-04 15:59:31,990: INFO: data_transformation: Splited data into training and test sets]
[2025-03-04 15:59:31,990: INFO: data_transformation: (1199, 12)]
[2025-03-04 15:59:31,990: INFO: data_transformation: (400, 12)]
[2025-03-04 15:59:31,990: INFO: main: >>>>>> stage Data Transformation Stage completed <<<<<

x=======x]
[2025-03-04 15:59:31,990: INFO: main: >>>>> stage Model Training Stage started <<<<<<]
[2025-03-04 15:59:31,992: INFO: common: yaml file: config/config.yaml loaded successfully]
[2025-03-04 15:59:31,993: INFO: common: yaml file: params.yaml loaded successfully]
[2025-03-04 15:59:31,995: INFO: common: yaml file: schema.yaml loaded successfully]
[2025-03-04 15:59:31,995: INFO: common: created directory at: artifacts]
[2025-03-04 15:59:31,995: INFO: common: created directory at: artifacts/model_trainer]
[2025-03-04 15:59:32,016: INFO: main: >>>>>> stage Model Training Stage completed <<<<<

x=======x]
[2025-03-05 14:15:57,409: INFO: main: >>>>> stage Data Ingestion Stage started <<<<<<]
[2025-03-05 14:15:57,414: INFO: common: yaml file: config/config.yaml loaded successfully]
[2025-03-05 14:15:57,418: INFO: common: yaml file: params.yaml loaded successfully]
[2025-03-05 14:15:57,422: INFO: common: yaml file: schema.yaml loaded successfully]
[2025-03-05 14:15:57,422: INFO: common: created directory at: artifacts]
[2025-03-05 14:15:57,422: INFO: common: created directory at: artifacts/data_ingestion]
[2025-03-05 14:15:57,422: INFO: data_ingestion: File already exists]
[2025-03-05 14:15:57,430: INFO: main: >>>>>> stage Data Ingestion Stage completed <<<<<

x=======x]
[2025-03-05 14:15:57,430: INFO: main: >>>>> stage Data Validation Stage started <<<<<<]
[2025-03-05 14:15:57,433: INFO: common: yaml file: config/config.yaml loaded successfully]
[2025-03-05 14:15:57,434: INFO: common: yaml file: params.yaml loaded successfully]
[2025-03-05 14:15:57,436: INFO: common: yaml file: schema.yaml loaded successfully]
[2025-03-05 14:15:57,437: INFO: common: created directory at: artifacts]
[2025-03-05 14:15:57,437: INFO: common: created directory at: artifacts/data_validation]
[2025-03-05 14:15:57,452: INFO: main: >>>>>> stage Data Validation Stage completed <<<<<

x=======x]
[2025-03-05 14:15:57,452: INFO: main: >>>>> stage Data Transformation Stage started <<<<<<]
[2025-03-05 14:15:57,455: INFO: common: yaml file: config/config.yaml loaded successfully]
[2025-03-05 14:15:57,456: INFO: common: yaml file: params.yaml loaded successfully]
[2025-03-05 14:15:57,458: INFO: common: yaml file: schema.yaml loaded successfully]
[2025-03-05 14:15:57,459: INFO: common: created directory at: artifacts]
[2025-03-05 14:15:57,459: INFO: common: created directory at: artifacts/data_transformation]
[2025-03-05 14:15:57,486: INFO: data_transformation: Splited data into training and test sets]
[2025-03-05 14:15:57,486: INFO: data_transformation: (1199, 12)]
[2025-03-05 14:15:57,486: INFO: data_transformation: (400, 12)]
[2025-03-05 14:15:57,486: INFO: main: >>>>>> stage Data Transformation Stage completed <<<<<

x=======x]
[2025-03-05 14:15:57,487: INFO: main: >>>>> stage Model Training Stage started <<<<<<]
[2025-03-05 14:15:57,490: INFO: common: yaml file: config/config.yaml loaded successfully]
[2025-03-05 14:15:57,491: INFO: common: yaml file: params.yaml loaded successfully]
[2025-03-05 14:15:57,494: INFO: common: yaml file: schema.yaml loaded successfully]
[2025-03-05 14:15:57,494: INFO: common: created directory at: artifacts]
[2025-03-05 14:15:57,494: INFO: common: created directory at: artifacts/model_trainer]
[2025-03-05 14:15:57,515: INFO: main: >>>>>> stage Model Training Stage completed <<<<<

x=======x]
[2025-03-05 14:15:57,515: INFO: main: >>>>> stage Model Evaluation Stage started <<<<<<]
[2025-03-05 14:15:57,518: INFO: common: yaml file: config/config.yaml loaded successfully]
[2025-03-05 14:15:57,520: INFO: common: yaml file: params.yaml loaded successfully]
[2025-03-05 14:15:57,522: INFO: common: yaml file: schema.yaml loaded successfully]
[2025-03-05 14:15:57,523: INFO: common: created directory at: artifacts]
[2025-03-05 14:15:57,523: INFO: common: created directory at: artifacts/model_trainer]
[2025-03-05 14:15:57,523: ERROR: main: "'ConfigBox' object has no attribute 'model_path'"]
Traceback (most recent call last):
  File "box/box.py", line 594, in box.box.Box.__getitem__
KeyError: 'model_path'

The above exception was the direct cause of the following exception:

Traceback (most recent call last):
  File "box/box.py", line 633, in box.box.Box.__getattr__
  File "box/box.py", line 621, in box.box.Box.__getitem__
box.exceptions.BoxKeyError: "'model_path'"

During handling of the above exception, another exception occurred:

Traceback (most recent call last):
  File "box/box.py", line 635, in box.box.Box.__getattr__
AttributeError: 'ConfigBox' object has no attribute 'model_path'

The above exception was the direct cause of the following exception:

Traceback (most recent call last):
  File "box/config_box.py", line 29, in box.config_box.ConfigBox.__getattr__
  File "box/box.py", line 649, in box.box.Box.__getattr__
box.exceptions.BoxKeyError: "'ConfigBox' object has no attribute 'model_path'"

During handling of the above exception, another exception occurred:

Traceback (most recent call last):
  File "box/box.py", line 594, in box.box.Box.__getitem__
KeyError: 'model_path'

The above exception was the direct cause of the following exception:

Traceback (most recent call last):
  File "box/box.py", line 633, in box.box.Box.__getattr__
  File "box/box.py", line 621, in box.box.Box.__getitem__
box.exceptions.BoxKeyError: "'model_path'"

During handling of the above exception, another exception occurred:

Traceback (most recent call last):
  File "box/box.py", line 635, in box.box.Box.__getattr__
AttributeError: 'ConfigBox' object has no attribute 'model_path'

The above exception was the direct cause of the following exception:

Traceback (most recent call last):
  File "/Users/neerajbhauryal/Desktop/ML projects/DS-Project/main.py", line 54, in <module>
    obj.initiate_model_evaluation()
  File "/Users/neerajbhauryal/Desktop/ML projects/DS-Project/src/DS_Project/pipeline/model_evaluation.py", line 13, in initiate_model_evaluation
    model_evaluation_config = config.get_model_evaluation_config()
  File "/Users/neerajbhauryal/Desktop/ML projects/DS-Project/src/DS_Project/config/configuration.py", line 81, in get_model_evaluation_config
    model_path = config.model_path,
  File "box/config_box.py", line 31, in box.config_box.ConfigBox.__getattr__
  File "box/box.py", line 649, in box.box.Box.__getattr__
box.exceptions.BoxKeyError: "'ConfigBox' object has no attribute 'model_path'"
[2025-03-05 14:18:12,015: INFO: main: >>>>> stage Data Ingestion Stage started <<<<<<]
[2025-03-05 14:18:12,018: INFO: common: yaml file: config/config.yaml loaded successfully]
[2025-03-05 14:18:12,019: INFO: common: yaml file: params.yaml loaded successfully]
[2025-03-05 14:18:12,020: INFO: common: yaml file: schema.yaml loaded successfully]
[2025-03-05 14:18:12,020: INFO: common: created directory at: artifacts]
[2025-03-05 14:18:12,020: INFO: common: created directory at: artifacts/data_ingestion]
[2025-03-05 14:18:12,021: INFO: data_ingestion: File already exists]
[2025-03-05 14:18:12,023: INFO: main: >>>>>> stage Data Ingestion Stage completed <<<<<

x=======x]
[2025-03-05 14:18:12,023: INFO: main: >>>>> stage Data Validation Stage started <<<<<<]
[2025-03-05 14:18:12,027: INFO: common: yaml file: config/config.yaml loaded successfully]
[2025-03-05 14:18:12,028: INFO: common: yaml file: params.yaml loaded successfully]
[2025-03-05 14:18:12,029: INFO: common: yaml file: schema.yaml loaded successfully]
[2025-03-05 14:18:12,030: INFO: common: created directory at: artifacts]
[2025-03-05 14:18:12,030: INFO: common: created directory at: artifacts/data_validation]
[2025-03-05 14:18:12,039: INFO: main: >>>>>> stage Data Validation Stage completed <<<<<

x=======x]
[2025-03-05 14:18:12,040: INFO: main: >>>>> stage Data Transformation Stage started <<<<<<]
[2025-03-05 14:18:12,043: INFO: common: yaml file: config/config.yaml loaded successfully]
[2025-03-05 14:18:12,044: INFO: common: yaml file: params.yaml loaded successfully]
[2025-03-05 14:18:12,047: INFO: common: yaml file: schema.yaml loaded successfully]
[2025-03-05 14:18:12,047: INFO: common: created directory at: artifacts]
[2025-03-05 14:18:12,047: INFO: common: created directory at: artifacts/data_transformation]
[2025-03-05 14:18:12,065: INFO: data_transformation: Splited data into training and test sets]
[2025-03-05 14:18:12,065: INFO: data_transformation: (1199, 12)]
[2025-03-05 14:18:12,065: INFO: data_transformation: (400, 12)]
[2025-03-05 14:18:12,065: INFO: main: >>>>>> stage Data Transformation Stage completed <<<<<

x=======x]
[2025-03-05 14:18:12,065: INFO: main: >>>>> stage Model Training Stage started <<<<<<]
[2025-03-05 14:18:12,067: INFO: common: yaml file: config/config.yaml loaded successfully]
[2025-03-05 14:18:12,068: INFO: common: yaml file: params.yaml loaded successfully]
[2025-03-05 14:18:12,070: INFO: common: yaml file: schema.yaml loaded successfully]
[2025-03-05 14:18:12,070: INFO: common: created directory at: artifacts]
[2025-03-05 14:18:12,070: INFO: common: created directory at: artifacts/model_trainer]
[2025-03-05 14:18:12,082: INFO: main: >>>>>> stage Model Training Stage completed <<<<<

x=======x]
[2025-03-05 14:18:12,082: INFO: main: >>>>> stage Model Evaluation Stage started <<<<<<]
[2025-03-05 14:18:12,085: INFO: common: yaml file: config/config.yaml loaded successfully]
[2025-03-05 14:18:12,086: INFO: common: yaml file: params.yaml loaded successfully]
[2025-03-05 14:18:12,087: INFO: common: yaml file: schema.yaml loaded successfully]
[2025-03-05 14:18:12,088: INFO: common: created directory at: artifacts]
[2025-03-05 14:18:12,088: INFO: common: created directory at: artifacts/model_trainer]
[2025-03-05 14:18:12,088: ERROR: main: "'ConfigBox' object has no attribute 'model_path'"]
Traceback (most recent call last):
  File "box/box.py", line 594, in box.box.Box.__getitem__
KeyError: 'model_path'

The above exception was the direct cause of the following exception:

Traceback (most recent call last):
  File "box/box.py", line 633, in box.box.Box.__getattr__
  File "box/box.py", line 621, in box.box.Box.__getitem__
box.exceptions.BoxKeyError: "'model_path'"

During handling of the above exception, another exception occurred:

Traceback (most recent call last):
  File "box/box.py", line 635, in box.box.Box.__getattr__
AttributeError: 'ConfigBox' object has no attribute 'model_path'

The above exception was the direct cause of the following exception:

Traceback (most recent call last):
  File "box/config_box.py", line 29, in box.config_box.ConfigBox.__getattr__
  File "box/box.py", line 649, in box.box.Box.__getattr__
box.exceptions.BoxKeyError: "'ConfigBox' object has no attribute 'model_path'"

During handling of the above exception, another exception occurred:

Traceback (most recent call last):
  File "box/box.py", line 594, in box.box.Box.__getitem__
KeyError: 'model_path'

The above exception was the direct cause of the following exception:

Traceback (most recent call last):
  File "box/box.py", line 633, in box.box.Box.__getattr__
  File "box/box.py", line 621, in box.box.Box.__getitem__
box.exceptions.BoxKeyError: "'model_path'"

During handling of the above exception, another exception occurred:

Traceback (most recent call last):
  File "box/box.py", line 635, in box.box.Box.__getattr__
AttributeError: 'ConfigBox' object has no attribute 'model_path'

The above exception was the direct cause of the following exception:

Traceback (most recent call last):
  File "/Users/neerajbhauryal/Desktop/ML projects/DS-Project/main.py", line 54, in <module>
    obj.initiate_model_evaluation()
  File "/Users/neerajbhauryal/Desktop/ML projects/DS-Project/src/DS_Project/pipeline/model_evaluation.py", line 13, in initiate_model_evaluation
    model_evaluation_config = config.get_model_evaluation_config()
  File "/Users/neerajbhauryal/Desktop/ML projects/DS-Project/src/DS_Project/config/configuration.py", line 81, in get_model_evaluation_config
    model_path = config.model_path,
  File "box/config_box.py", line 31, in box.config_box.ConfigBox.__getattr__
  File "box/box.py", line 649, in box.box.Box.__getattr__
box.exceptions.BoxKeyError: "'ConfigBox' object has no attribute 'model_path'"
[2025-03-05 14:30:36,172: INFO: main: >>>>> stage Data Ingestion Stage started <<<<<<]
[2025-03-05 14:30:36,181: INFO: common: yaml file: config/config.yaml loaded successfully]
[2025-03-05 14:30:36,185: INFO: common: yaml file: params.yaml loaded successfully]
[2025-03-05 14:30:36,189: INFO: common: yaml file: schema.yaml loaded successfully]
[2025-03-05 14:30:36,190: INFO: common: created directory at: artifacts]
[2025-03-05 14:30:36,190: INFO: common: created directory at: artifacts/data_ingestion]
[2025-03-05 14:30:36,190: INFO: data_ingestion: File already exists]
[2025-03-05 14:30:36,196: INFO: main: >>>>>> stage Data Ingestion Stage completed <<<<<

x=======x]
[2025-03-05 14:30:36,196: INFO: main: >>>>> stage Data Validation Stage started <<<<<<]
[2025-03-05 14:30:36,200: INFO: common: yaml file: config/config.yaml loaded successfully]
[2025-03-05 14:30:36,202: INFO: common: yaml file: params.yaml loaded successfully]
[2025-03-05 14:30:36,205: INFO: common: yaml file: schema.yaml loaded successfully]
[2025-03-05 14:30:36,205: INFO: common: created directory at: artifacts]
[2025-03-05 14:30:36,205: INFO: common: created directory at: artifacts/data_validation]
[2025-03-05 14:30:36,223: INFO: main: >>>>>> stage Data Validation Stage completed <<<<<

x=======x]
[2025-03-05 14:30:36,224: INFO: main: >>>>> stage Data Transformation Stage started <<<<<<]
[2025-03-05 14:30:36,226: INFO: common: yaml file: config/config.yaml loaded successfully]
[2025-03-05 14:30:36,227: INFO: common: yaml file: params.yaml loaded successfully]
[2025-03-05 14:30:36,228: INFO: common: yaml file: schema.yaml loaded successfully]
[2025-03-05 14:30:36,228: INFO: common: created directory at: artifacts]
[2025-03-05 14:30:36,229: INFO: common: created directory at: artifacts/data_transformation]
[2025-03-05 14:30:36,255: INFO: data_transformation: Splited data into training and test sets]
[2025-03-05 14:30:36,256: INFO: data_transformation: (1199, 12)]
[2025-03-05 14:30:36,256: INFO: data_transformation: (400, 12)]
[2025-03-05 14:30:36,256: INFO: main: >>>>>> stage Data Transformation Stage completed <<<<<

x=======x]
[2025-03-05 14:30:36,256: INFO: main: >>>>> stage Model Training Stage started <<<<<<]
[2025-03-05 14:30:36,259: INFO: common: yaml file: config/config.yaml loaded successfully]
[2025-03-05 14:30:36,259: INFO: common: yaml file: params.yaml loaded successfully]
[2025-03-05 14:30:36,261: INFO: common: yaml file: schema.yaml loaded successfully]
[2025-03-05 14:30:36,261: INFO: common: created directory at: artifacts]
[2025-03-05 14:30:36,261: INFO: common: created directory at: artifacts/model_trainer]
[2025-03-05 14:30:36,276: INFO: main: >>>>>> stage Model Training Stage completed <<<<<

x=======x]
[2025-03-05 14:30:36,276: INFO: main: >>>>> stage Model Evaluation Stage started <<<<<<]
[2025-03-05 14:30:36,278: INFO: common: yaml file: config/config.yaml loaded successfully]
[2025-03-05 14:30:36,279: INFO: common: yaml file: params.yaml loaded successfully]
[2025-03-05 14:30:36,281: INFO: common: yaml file: schema.yaml loaded successfully]
[2025-03-05 14:30:36,281: INFO: common: created directory at: artifacts]
[2025-03-05 14:30:36,281: INFO: common: created directory at: artifacts/model_trainer]
[2025-03-05 14:30:36,282: ERROR: main: "'ConfigBox' object has no attribute 'model_path'"]
Traceback (most recent call last):
  File "box/box.py", line 594, in box.box.Box.__getitem__
KeyError: 'model_path'

The above exception was the direct cause of the following exception:

Traceback (most recent call last):
  File "box/box.py", line 633, in box.box.Box.__getattr__
  File "box/box.py", line 621, in box.box.Box.__getitem__
box.exceptions.BoxKeyError: "'model_path'"

During handling of the above exception, another exception occurred:

Traceback (most recent call last):
  File "box/box.py", line 635, in box.box.Box.__getattr__
AttributeError: 'ConfigBox' object has no attribute 'model_path'

The above exception was the direct cause of the following exception:

Traceback (most recent call last):
  File "box/config_box.py", line 29, in box.config_box.ConfigBox.__getattr__
  File "box/box.py", line 649, in box.box.Box.__getattr__
box.exceptions.BoxKeyError: "'ConfigBox' object has no attribute 'model_path'"

During handling of the above exception, another exception occurred:

Traceback (most recent call last):
  File "box/box.py", line 594, in box.box.Box.__getitem__
KeyError: 'model_path'

The above exception was the direct cause of the following exception:

Traceback (most recent call last):
  File "box/box.py", line 633, in box.box.Box.__getattr__
  File "box/box.py", line 621, in box.box.Box.__getitem__
box.exceptions.BoxKeyError: "'model_path'"

During handling of the above exception, another exception occurred:

Traceback (most recent call last):
  File "box/box.py", line 635, in box.box.Box.__getattr__
AttributeError: 'ConfigBox' object has no attribute 'model_path'

The above exception was the direct cause of the following exception:

Traceback (most recent call last):
  File "/Users/neerajbhauryal/Desktop/ML projects/DS-Project/main.py", line 54, in <module>
    obj.initiate_model_evaluation()
  File "/Users/neerajbhauryal/Desktop/ML projects/DS-Project/src/DS_Project/pipeline/model_evaluation.py", line 13, in initiate_model_evaluation
    model_evaluation_config = config.get_model_evaluation_config()
  File "/Users/neerajbhauryal/Desktop/ML projects/DS-Project/src/DS_Project/config/configuration.py", line 81, in get_model_evaluation_config
    model_path = config.model_path,
  File "box/config_box.py", line 31, in box.config_box.ConfigBox.__getattr__
  File "box/box.py", line 649, in box.box.Box.__getattr__
box.exceptions.BoxKeyError: "'ConfigBox' object has no attribute 'model_path'"
[2025-03-05 14:32:12,194: INFO: main: >>>>> stage Data Ingestion Stage started <<<<<<]
[2025-03-05 14:32:12,197: INFO: common: yaml file: config/config.yaml loaded successfully]
[2025-03-05 14:32:12,198: INFO: common: yaml file: params.yaml loaded successfully]
[2025-03-05 14:32:12,201: INFO: common: yaml file: schema.yaml loaded successfully]
[2025-03-05 14:32:12,202: INFO: common: created directory at: artifacts]
[2025-03-05 14:32:12,202: INFO: common: created directory at: artifacts/data_ingestion]
[2025-03-05 14:32:12,202: INFO: data_ingestion: File already exists]
[2025-03-05 14:32:12,204: INFO: main: >>>>>> stage Data Ingestion Stage completed <<<<<

x=======x]
[2025-03-05 14:32:12,204: INFO: main: >>>>> stage Data Validation Stage started <<<<<<]
[2025-03-05 14:32:12,207: INFO: common: yaml file: config/config.yaml loaded successfully]
[2025-03-05 14:32:12,208: INFO: common: yaml file: params.yaml loaded successfully]
[2025-03-05 14:32:12,210: INFO: common: yaml file: schema.yaml loaded successfully]
[2025-03-05 14:32:12,211: INFO: common: created directory at: artifacts]
[2025-03-05 14:32:12,211: INFO: common: created directory at: artifacts/data_validation]
[2025-03-05 14:32:12,220: INFO: main: >>>>>> stage Data Validation Stage completed <<<<<

x=======x]
[2025-03-05 14:32:12,220: INFO: main: >>>>> stage Data Transformation Stage started <<<<<<]
[2025-03-05 14:32:12,224: INFO: common: yaml file: config/config.yaml loaded successfully]
[2025-03-05 14:32:12,225: INFO: common: yaml file: params.yaml loaded successfully]
[2025-03-05 14:32:12,228: INFO: common: yaml file: schema.yaml loaded successfully]
[2025-03-05 14:32:12,229: INFO: common: created directory at: artifacts]
[2025-03-05 14:32:12,229: INFO: common: created directory at: artifacts/data_transformation]
[2025-03-05 14:32:12,250: INFO: data_transformation: Splited data into training and test sets]
[2025-03-05 14:32:12,250: INFO: data_transformation: (1199, 12)]
[2025-03-05 14:32:12,250: INFO: data_transformation: (400, 12)]
[2025-03-05 14:32:12,250: INFO: main: >>>>>> stage Data Transformation Stage completed <<<<<

x=======x]
[2025-03-05 14:32:12,250: INFO: main: >>>>> stage Model Training Stage started <<<<<<]
[2025-03-05 14:32:12,253: INFO: common: yaml file: config/config.yaml loaded successfully]
[2025-03-05 14:32:12,254: INFO: common: yaml file: params.yaml loaded successfully]
[2025-03-05 14:32:12,257: INFO: common: yaml file: schema.yaml loaded successfully]
[2025-03-05 14:32:12,257: INFO: common: created directory at: artifacts]
[2025-03-05 14:32:12,258: INFO: common: created directory at: artifacts/model_trainer]
[2025-03-05 14:32:12,273: INFO: main: >>>>>> stage Model Training Stage completed <<<<<

x=======x]
[2025-03-05 14:32:12,273: INFO: main: >>>>> stage Model Evaluation Stage started <<<<<<]
[2025-03-05 14:32:12,276: INFO: common: yaml file: config/config.yaml loaded successfully]
[2025-03-05 14:32:12,278: INFO: common: yaml file: params.yaml loaded successfully]
[2025-03-05 14:32:12,281: INFO: common: yaml file: schema.yaml loaded successfully]
[2025-03-05 14:32:12,281: INFO: common: created directory at: artifacts]
[2025-03-05 14:32:12,282: INFO: common: created directory at: artifacts/model_trainer]
[2025-03-05 14:32:12,282: ERROR: main: "'ConfigBox' object has no attribute 'model_path'"]
Traceback (most recent call last):
  File "box/box.py", line 594, in box.box.Box.__getitem__
KeyError: 'model_path'

The above exception was the direct cause of the following exception:

Traceback (most recent call last):
  File "box/box.py", line 633, in box.box.Box.__getattr__
  File "box/box.py", line 621, in box.box.Box.__getitem__
box.exceptions.BoxKeyError: "'model_path'"

During handling of the above exception, another exception occurred:

Traceback (most recent call last):
  File "box/box.py", line 635, in box.box.Box.__getattr__
AttributeError: 'ConfigBox' object has no attribute 'model_path'

The above exception was the direct cause of the following exception:

Traceback (most recent call last):
  File "box/config_box.py", line 29, in box.config_box.ConfigBox.__getattr__
  File "box/box.py", line 649, in box.box.Box.__getattr__
box.exceptions.BoxKeyError: "'ConfigBox' object has no attribute 'model_path'"

During handling of the above exception, another exception occurred:

Traceback (most recent call last):
  File "box/box.py", line 594, in box.box.Box.__getitem__
KeyError: 'model_path'

The above exception was the direct cause of the following exception:

Traceback (most recent call last):
  File "box/box.py", line 633, in box.box.Box.__getattr__
  File "box/box.py", line 621, in box.box.Box.__getitem__
box.exceptions.BoxKeyError: "'model_path'"

During handling of the above exception, another exception occurred:

Traceback (most recent call last):
  File "box/box.py", line 635, in box.box.Box.__getattr__
AttributeError: 'ConfigBox' object has no attribute 'model_path'

The above exception was the direct cause of the following exception:

Traceback (most recent call last):
  File "/Users/neerajbhauryal/Desktop/ML projects/DS-Project/main.py", line 54, in <module>
    obj.initiate_model_evaluation()
  File "/Users/neerajbhauryal/Desktop/ML projects/DS-Project/src/DS_Project/pipeline/model_evaluation.py", line 13, in initiate_model_evaluation
    model_evaluation_config = config.get_model_evaluation_config()
  File "/Users/neerajbhauryal/Desktop/ML projects/DS-Project/src/DS_Project/config/configuration.py", line 81, in get_model_evaluation_config
    model_path = config.model_path,
  File "box/config_box.py", line 31, in box.config_box.ConfigBox.__getattr__
  File "box/box.py", line 649, in box.box.Box.__getattr__
box.exceptions.BoxKeyError: "'ConfigBox' object has no attribute 'model_path'"
[2025-03-05 14:35:47,487: INFO: main: >>>>> stage Data Ingestion Stage started <<<<<<]
[2025-03-05 14:35:47,491: INFO: common: yaml file: config/config.yaml loaded successfully]
[2025-03-05 14:35:47,497: INFO: common: yaml file: params.yaml loaded successfully]
[2025-03-05 14:35:47,501: INFO: common: yaml file: schema.yaml loaded successfully]
[2025-03-05 14:35:47,502: INFO: common: created directory at: artifacts]
[2025-03-05 14:35:47,502: INFO: common: created directory at: artifacts/data_ingestion]
[2025-03-05 14:35:47,502: INFO: data_ingestion: File already exists]
[2025-03-05 14:35:47,508: INFO: main: >>>>>> stage Data Ingestion Stage completed <<<<<

x=======x]
[2025-03-05 14:35:47,508: INFO: main: >>>>> stage Data Validation Stage started <<<<<<]
[2025-03-05 14:35:47,511: INFO: common: yaml file: config/config.yaml loaded successfully]
[2025-03-05 14:35:47,512: INFO: common: yaml file: params.yaml loaded successfully]
[2025-03-05 14:35:47,514: INFO: common: yaml file: schema.yaml loaded successfully]
[2025-03-05 14:35:47,514: INFO: common: created directory at: artifacts]
[2025-03-05 14:35:47,514: INFO: common: created directory at: artifacts/data_validation]
[2025-03-05 14:35:47,534: INFO: main: >>>>>> stage Data Validation Stage completed <<<<<

x=======x]
[2025-03-05 14:35:47,534: INFO: main: >>>>> stage Data Transformation Stage started <<<<<<]
[2025-03-05 14:35:47,537: INFO: common: yaml file: config/config.yaml loaded successfully]
[2025-03-05 14:35:47,538: INFO: common: yaml file: params.yaml loaded successfully]
[2025-03-05 14:35:47,540: INFO: common: yaml file: schema.yaml loaded successfully]
[2025-03-05 14:35:47,540: INFO: common: created directory at: artifacts]
[2025-03-05 14:35:47,541: INFO: common: created directory at: artifacts/data_transformation]
[2025-03-05 14:35:47,571: INFO: data_transformation: Splited data into training and test sets]
[2025-03-05 14:35:47,571: INFO: data_transformation: (1199, 12)]
[2025-03-05 14:35:47,571: INFO: data_transformation: (400, 12)]
[2025-03-05 14:35:47,571: INFO: main: >>>>>> stage Data Transformation Stage completed <<<<<

x=======x]
[2025-03-05 14:35:47,571: INFO: main: >>>>> stage Model Training Stage started <<<<<<]
[2025-03-05 14:35:47,574: INFO: common: yaml file: config/config.yaml loaded successfully]
[2025-03-05 14:35:47,574: INFO: common: yaml file: params.yaml loaded successfully]
[2025-03-05 14:35:47,576: INFO: common: yaml file: schema.yaml loaded successfully]
[2025-03-05 14:35:47,577: INFO: common: created directory at: artifacts]
[2025-03-05 14:35:47,577: INFO: common: created directory at: artifacts/model_trainer]
[2025-03-05 14:35:47,591: INFO: main: >>>>>> stage Model Training Stage completed <<<<<

x=======x]
[2025-03-05 14:35:47,591: INFO: main: >>>>> stage Model Evaluation Stage started <<<<<<]
[2025-03-05 14:35:47,595: INFO: common: yaml file: config/config.yaml loaded successfully]
[2025-03-05 14:35:47,596: INFO: common: yaml file: params.yaml loaded successfully]
[2025-03-05 14:35:47,597: INFO: common: yaml file: schema.yaml loaded successfully]
[2025-03-05 14:35:47,598: INFO: common: created directory at: artifacts]
[2025-03-05 14:35:47,598: INFO: common: created directory at: artifacts/model_trainer]
[2025-03-05 14:35:47,599: ERROR: main: "'ConfigBox' object has no attribute 'metric_file_name'"]
Traceback (most recent call last):
  File "box/box.py", line 594, in box.box.Box.__getitem__
KeyError: 'metric_file_name'

The above exception was the direct cause of the following exception:

Traceback (most recent call last):
  File "box/box.py", line 633, in box.box.Box.__getattr__
  File "box/box.py", line 621, in box.box.Box.__getitem__
box.exceptions.BoxKeyError: "'metric_file_name'"

During handling of the above exception, another exception occurred:

Traceback (most recent call last):
  File "box/box.py", line 635, in box.box.Box.__getattr__
AttributeError: 'ConfigBox' object has no attribute 'metric_file_name'

The above exception was the direct cause of the following exception:

Traceback (most recent call last):
  File "box/config_box.py", line 29, in box.config_box.ConfigBox.__getattr__
  File "box/box.py", line 649, in box.box.Box.__getattr__
box.exceptions.BoxKeyError: "'ConfigBox' object has no attribute 'metric_file_name'"

During handling of the above exception, another exception occurred:

Traceback (most recent call last):
  File "box/box.py", line 594, in box.box.Box.__getitem__
KeyError: 'metric_file_name'

The above exception was the direct cause of the following exception:

Traceback (most recent call last):
  File "box/box.py", line 633, in box.box.Box.__getattr__
  File "box/box.py", line 621, in box.box.Box.__getitem__
box.exceptions.BoxKeyError: "'metric_file_name'"

During handling of the above exception, another exception occurred:

Traceback (most recent call last):
  File "box/box.py", line 635, in box.box.Box.__getattr__
AttributeError: 'ConfigBox' object has no attribute 'metric_file_name'

The above exception was the direct cause of the following exception:

Traceback (most recent call last):
  File "/Users/neerajbhauryal/Desktop/ML projects/DS-Project/main.py", line 54, in <module>
    obj.initiate_model_evaluation()
  File "/Users/neerajbhauryal/Desktop/ML projects/DS-Project/src/DS_Project/pipeline/model_evaluation.py", line 13, in initiate_model_evaluation
    model_evaluation_config = config.get_model_evaluation_config()
  File "/Users/neerajbhauryal/Desktop/ML projects/DS-Project/src/DS_Project/config/configuration.py", line 83, in get_model_evaluation_config
    metric_file_name= config.metric_file_name,
  File "box/config_box.py", line 31, in box.config_box.ConfigBox.__getattr__
  File "box/box.py", line 649, in box.box.Box.__getattr__
box.exceptions.BoxKeyError: "'ConfigBox' object has no attribute 'metric_file_name'"
[2025-03-05 14:38:22,500: INFO: main: >>>>> stage Data Ingestion Stage started <<<<<<]
[2025-03-05 14:38:22,504: INFO: common: yaml file: config/config.yaml loaded successfully]
[2025-03-05 14:38:22,506: INFO: common: yaml file: params.yaml loaded successfully]
[2025-03-05 14:38:22,509: INFO: common: yaml file: schema.yaml loaded successfully]
[2025-03-05 14:38:22,510: INFO: common: created directory at: artifacts]
[2025-03-05 14:38:22,510: INFO: common: created directory at: artifacts/data_ingestion]
[2025-03-05 14:38:22,510: INFO: data_ingestion: File already exists]
[2025-03-05 14:38:22,515: INFO: main: >>>>>> stage Data Ingestion Stage completed <<<<<

x=======x]
[2025-03-05 14:38:22,516: INFO: main: >>>>> stage Data Validation Stage started <<<<<<]
[2025-03-05 14:38:22,518: INFO: common: yaml file: config/config.yaml loaded successfully]
[2025-03-05 14:38:22,519: INFO: common: yaml file: params.yaml loaded successfully]
[2025-03-05 14:38:22,521: INFO: common: yaml file: schema.yaml loaded successfully]
[2025-03-05 14:38:22,521: INFO: common: created directory at: artifacts]
[2025-03-05 14:38:22,521: INFO: common: created directory at: artifacts/data_validation]
[2025-03-05 14:38:22,530: INFO: main: >>>>>> stage Data Validation Stage completed <<<<<

x=======x]
[2025-03-05 14:38:22,530: INFO: main: >>>>> stage Data Transformation Stage started <<<<<<]
[2025-03-05 14:38:22,533: INFO: common: yaml file: config/config.yaml loaded successfully]
[2025-03-05 14:38:22,534: INFO: common: yaml file: params.yaml loaded successfully]
[2025-03-05 14:38:22,537: INFO: common: yaml file: schema.yaml loaded successfully]
[2025-03-05 14:38:22,537: INFO: common: created directory at: artifacts]
[2025-03-05 14:38:22,537: INFO: common: created directory at: artifacts/data_transformation]
[2025-03-05 14:38:22,555: INFO: data_transformation: Splited data into training and test sets]
[2025-03-05 14:38:22,555: INFO: data_transformation: (1199, 12)]
[2025-03-05 14:38:22,555: INFO: data_transformation: (400, 12)]
[2025-03-05 14:38:22,556: INFO: main: >>>>>> stage Data Transformation Stage completed <<<<<

x=======x]
[2025-03-05 14:38:22,556: INFO: main: >>>>> stage Model Training Stage started <<<<<<]
[2025-03-05 14:38:22,559: INFO: common: yaml file: config/config.yaml loaded successfully]
[2025-03-05 14:38:22,559: INFO: common: yaml file: params.yaml loaded successfully]
[2025-03-05 14:38:22,561: INFO: common: yaml file: schema.yaml loaded successfully]
[2025-03-05 14:38:22,561: INFO: common: created directory at: artifacts]
[2025-03-05 14:38:22,561: INFO: common: created directory at: artifacts/model_trainer]
[2025-03-05 14:38:22,572: INFO: main: >>>>>> stage Model Training Stage completed <<<<<

x=======x]
[2025-03-05 14:38:22,573: INFO: main: >>>>> stage Model Evaluation Stage started <<<<<<]
[2025-03-05 14:38:22,575: INFO: common: yaml file: config/config.yaml loaded successfully]
[2025-03-05 14:38:22,576: INFO: common: yaml file: params.yaml loaded successfully]
[2025-03-05 14:38:22,578: INFO: common: yaml file: schema.yaml loaded successfully]
[2025-03-05 14:38:22,578: INFO: common: created directory at: artifacts]
[2025-03-05 14:38:22,578: INFO: common: created directory at: artifacts/model_trainer]
[2025-03-05 14:38:22,578: ERROR: main: "'ConfigBox' object has no attribute 'metric_file_name'"]
Traceback (most recent call last):
  File "box/box.py", line 594, in box.box.Box.__getitem__
KeyError: 'metric_file_name'

The above exception was the direct cause of the following exception:

Traceback (most recent call last):
  File "box/box.py", line 633, in box.box.Box.__getattr__
  File "box/box.py", line 621, in box.box.Box.__getitem__
box.exceptions.BoxKeyError: "'metric_file_name'"

During handling of the above exception, another exception occurred:

Traceback (most recent call last):
  File "box/box.py", line 635, in box.box.Box.__getattr__
AttributeError: 'ConfigBox' object has no attribute 'metric_file_name'

The above exception was the direct cause of the following exception:

Traceback (most recent call last):
  File "box/config_box.py", line 29, in box.config_box.ConfigBox.__getattr__
  File "box/box.py", line 649, in box.box.Box.__getattr__
box.exceptions.BoxKeyError: "'ConfigBox' object has no attribute 'metric_file_name'"

During handling of the above exception, another exception occurred:

Traceback (most recent call last):
  File "box/box.py", line 594, in box.box.Box.__getitem__
KeyError: 'metric_file_name'

The above exception was the direct cause of the following exception:

Traceback (most recent call last):
  File "box/box.py", line 633, in box.box.Box.__getattr__
  File "box/box.py", line 621, in box.box.Box.__getitem__
box.exceptions.BoxKeyError: "'metric_file_name'"

During handling of the above exception, another exception occurred:

Traceback (most recent call last):
  File "box/box.py", line 635, in box.box.Box.__getattr__
AttributeError: 'ConfigBox' object has no attribute 'metric_file_name'

The above exception was the direct cause of the following exception:

Traceback (most recent call last):
  File "/Users/neerajbhauryal/Desktop/ML projects/DS-Project/main.py", line 54, in <module>
    obj.initiate_model_evaluation()
  File "/Users/neerajbhauryal/Desktop/ML projects/DS-Project/src/DS_Project/pipeline/model_evaluation.py", line 13, in initiate_model_evaluation
    model_evaluation_config = config.get_model_evaluation_config()
  File "/Users/neerajbhauryal/Desktop/ML projects/DS-Project/src/DS_Project/config/configuration.py", line 83, in get_model_evaluation_config
    metric_file_name= config.metric_file_name,
  File "box/config_box.py", line 31, in box.config_box.ConfigBox.__getattr__
  File "box/box.py", line 649, in box.box.Box.__getattr__
box.exceptions.BoxKeyError: "'ConfigBox' object has no attribute 'metric_file_name'"
[2025-03-05 14:44:14,345: INFO: main: >>>>> stage Data Ingestion Stage started <<<<<<]
[2025-03-05 14:44:14,348: INFO: common: yaml file: config/config.yaml loaded successfully]
[2025-03-05 14:44:14,349: INFO: common: yaml file: params.yaml loaded successfully]
[2025-03-05 14:44:14,351: INFO: common: yaml file: schema.yaml loaded successfully]
[2025-03-05 14:44:14,351: INFO: common: created directory at: artifacts]
[2025-03-05 14:44:14,351: INFO: common: created directory at: artifacts/data_ingestion]
[2025-03-05 14:44:14,351: INFO: data_ingestion: File already exists]
[2025-03-05 14:44:14,353: INFO: main: >>>>>> stage Data Ingestion Stage completed <<<<<

x=======x]
[2025-03-05 14:44:14,353: INFO: main: >>>>> stage Data Validation Stage started <<<<<<]
[2025-03-05 14:44:14,356: INFO: common: yaml file: config/config.yaml loaded successfully]
[2025-03-05 14:44:14,357: INFO: common: yaml file: params.yaml loaded successfully]
[2025-03-05 14:44:14,360: INFO: common: yaml file: schema.yaml loaded successfully]
[2025-03-05 14:44:14,361: INFO: common: created directory at: artifacts]
[2025-03-05 14:44:14,361: INFO: common: created directory at: artifacts/data_validation]
[2025-03-05 14:44:14,372: INFO: main: >>>>>> stage Data Validation Stage completed <<<<<

x=======x]
[2025-03-05 14:44:14,372: INFO: main: >>>>> stage Data Transformation Stage started <<<<<<]
[2025-03-05 14:44:14,375: INFO: common: yaml file: config/config.yaml loaded successfully]
[2025-03-05 14:44:14,375: INFO: common: yaml file: params.yaml loaded successfully]
[2025-03-05 14:44:14,378: INFO: common: yaml file: schema.yaml loaded successfully]
[2025-03-05 14:44:14,378: INFO: common: created directory at: artifacts]
[2025-03-05 14:44:14,378: INFO: common: created directory at: artifacts/data_transformation]
[2025-03-05 14:44:14,396: INFO: data_transformation: Splited data into training and test sets]
[2025-03-05 14:44:14,397: INFO: data_transformation: (1199, 12)]
[2025-03-05 14:44:14,397: INFO: data_transformation: (400, 12)]
[2025-03-05 14:44:14,397: INFO: main: >>>>>> stage Data Transformation Stage completed <<<<<

x=======x]
[2025-03-05 14:44:14,398: INFO: main: >>>>> stage Model Training Stage started <<<<<<]
[2025-03-05 14:44:14,402: INFO: common: yaml file: config/config.yaml loaded successfully]
[2025-03-05 14:44:14,404: INFO: common: yaml file: params.yaml loaded successfully]
[2025-03-05 14:44:14,406: INFO: common: yaml file: schema.yaml loaded successfully]
[2025-03-05 14:44:14,407: INFO: common: created directory at: artifacts]
[2025-03-05 14:44:14,407: INFO: common: created directory at: artifacts/model_trainer]
[2025-03-05 14:44:14,419: INFO: main: >>>>>> stage Model Training Stage completed <<<<<

x=======x]
[2025-03-05 14:44:14,419: INFO: main: >>>>> stage Model Evaluation Stage started <<<<<<]
[2025-03-05 14:44:14,423: INFO: common: yaml file: config/config.yaml loaded successfully]
[2025-03-05 14:44:14,424: INFO: common: yaml file: params.yaml loaded successfully]
[2025-03-05 14:44:14,426: INFO: common: yaml file: schema.yaml loaded successfully]
[2025-03-05 14:44:14,427: INFO: common: created directory at: artifacts]
[2025-03-05 14:44:14,427: INFO: common: created directory at: artifacts/model_evaluation]
[2025-03-05 14:44:15,286: INFO: common: json file saved at: artifacts/model_evaluation/metrics.json]
[2025-03-05 14:44:22,306: INFO: main: >>>>>> stage Model Evaluation Stage completed <<<<<

x=======x]
[2025-03-05 14:57:20,632: INFO: main: >>>>> stage Data Ingestion Stage started <<<<<<]
[2025-03-05 14:57:20,641: INFO: common: yaml file: config/config.yaml loaded successfully]
[2025-03-05 14:57:20,646: INFO: common: yaml file: params.yaml loaded successfully]
[2025-03-05 14:57:20,648: INFO: common: yaml file: schema.yaml loaded successfully]
[2025-03-05 14:57:20,649: INFO: common: created directory at: artifacts]
[2025-03-05 14:57:20,649: INFO: common: created directory at: artifacts/data_ingestion]
[2025-03-05 14:57:20,650: INFO: data_ingestion: File already exists]
[2025-03-05 14:57:20,655: INFO: main: >>>>>> stage Data Ingestion Stage completed <<<<<

x=======x]
[2025-03-05 14:57:20,655: INFO: main: >>>>> stage Data Validation Stage started <<<<<<]
[2025-03-05 14:57:20,658: INFO: common: yaml file: config/config.yaml loaded successfully]
[2025-03-05 14:57:20,659: INFO: common: yaml file: params.yaml loaded successfully]
[2025-03-05 14:57:20,661: INFO: common: yaml file: schema.yaml loaded successfully]
[2025-03-05 14:57:20,661: INFO: common: created directory at: artifacts]
[2025-03-05 14:57:20,661: INFO: common: created directory at: artifacts/data_validation]
[2025-03-05 14:57:20,677: INFO: main: >>>>>> stage Data Validation Stage completed <<<<<

x=======x]
[2025-03-05 14:57:20,677: INFO: main: >>>>> stage Data Transformation Stage started <<<<<<]
[2025-03-05 14:57:20,683: INFO: common: yaml file: config/config.yaml loaded successfully]
[2025-03-05 14:57:20,684: INFO: common: yaml file: params.yaml loaded successfully]
[2025-03-05 14:57:20,688: INFO: common: yaml file: schema.yaml loaded successfully]
[2025-03-05 14:57:20,688: INFO: common: created directory at: artifacts]
[2025-03-05 14:57:20,689: INFO: common: created directory at: artifacts/data_transformation]
[2025-03-05 14:57:20,717: INFO: data_transformation: Splited data into training and test sets]
[2025-03-05 14:57:20,717: INFO: data_transformation: (1199, 12)]
[2025-03-05 14:57:20,718: INFO: data_transformation: (400, 12)]
[2025-03-05 14:57:20,718: INFO: main: >>>>>> stage Data Transformation Stage completed <<<<<

x=======x]
[2025-03-05 14:57:20,718: INFO: main: >>>>> stage Model Training Stage started <<<<<<]
[2025-03-05 14:57:20,723: INFO: common: yaml file: config/config.yaml loaded successfully]
[2025-03-05 14:57:20,724: INFO: common: yaml file: params.yaml loaded successfully]
[2025-03-05 14:57:20,727: INFO: common: yaml file: schema.yaml loaded successfully]
[2025-03-05 14:57:20,727: INFO: common: created directory at: artifacts]
[2025-03-05 14:57:20,727: INFO: common: created directory at: artifacts/model_trainer]
[2025-03-05 14:57:20,748: INFO: main: >>>>>> stage Model Training Stage completed <<<<<

x=======x]
[2025-03-05 14:57:20,748: INFO: main: >>>>> stage Model Evaluation Stage started <<<<<<]
[2025-03-05 14:57:20,751: INFO: common: yaml file: config/config.yaml loaded successfully]
[2025-03-05 14:57:20,752: INFO: common: yaml file: params.yaml loaded successfully]
[2025-03-05 14:57:20,754: INFO: common: yaml file: schema.yaml loaded successfully]
[2025-03-05 14:57:20,755: INFO: common: created directory at: artifacts]
[2025-03-05 14:57:20,755: INFO: common: created directory at: artifacts/model_evaluation]
[2025-03-05 14:57:21,942: INFO: common: json file saved at: artifacts/model_evaluation/metrics.json]
[2025-03-05 14:57:32,253: INFO: main: >>>>>> stage Model Evaluation Stage completed <<<<<

x=======x]
[2025-03-05 16:18:15,653: INFO: _internal: [31m[1mWARNING: This is a development server. Do not use it in a production deployment. Use a production WSGI server instead.[0m
 * Running on all addresses (0.0.0.0)
 * Running on http://127.0.0.1:8080
 * Running on http://192.168.22.204:8080]
[2025-03-05 16:18:15,657: INFO: _internal: [33mPress CTRL+C to quit[0m]
[2025-03-05 16:19:06,747: INFO: _internal: 127.0.0.1 - - [05/Mar/2025 16:19:06] "GET / HTTP/1.1" 200 -]
[2025-03-05 16:19:06,790: INFO: _internal: 127.0.0.1 - - [05/Mar/2025 16:19:06] "[33mGET /static/assets/img/form-v9.jpg HTTP/1.1[0m" 404 -]
[2025-03-05 16:19:06,832: INFO: _internal: 127.0.0.1 - - [05/Mar/2025 16:19:06] "[33mGET /favicon.ico HTTP/1.1[0m" 404 -]
[2025-03-05 16:19:31,040: INFO: main: >>>>> stage Data Ingestion Stage started <<<<<<]
[2025-03-05 16:19:31,045: INFO: common: yaml file: config/config.yaml loaded successfully]
[2025-03-05 16:19:31,050: INFO: common: yaml file: params.yaml loaded successfully]
[2025-03-05 16:19:31,052: INFO: common: yaml file: schema.yaml loaded successfully]
[2025-03-05 16:19:31,052: INFO: common: created directory at: artifacts]
[2025-03-05 16:19:31,052: INFO: common: created directory at: artifacts/data_ingestion]
[2025-03-05 16:19:31,053: INFO: data_ingestion: File already exists]
[2025-03-05 16:19:31,057: INFO: main: >>>>>> stage Data Ingestion Stage completed <<<<<

x=======x]
[2025-03-05 16:19:31,057: INFO: main: >>>>> stage Data Validation Stage started <<<<<<]
[2025-03-05 16:19:31,060: INFO: common: yaml file: config/config.yaml loaded successfully]
[2025-03-05 16:19:31,061: INFO: common: yaml file: params.yaml loaded successfully]
[2025-03-05 16:19:31,062: INFO: common: yaml file: schema.yaml loaded successfully]
[2025-03-05 16:19:31,063: INFO: common: created directory at: artifacts]
[2025-03-05 16:19:31,063: INFO: common: created directory at: artifacts/data_validation]
[2025-03-05 16:19:31,088: INFO: main: >>>>>> stage Data Validation Stage completed <<<<<

x=======x]
[2025-03-05 16:19:31,088: INFO: main: >>>>> stage Data Transformation Stage started <<<<<<]
[2025-03-05 16:19:31,091: INFO: common: yaml file: config/config.yaml loaded successfully]
[2025-03-05 16:19:31,092: INFO: common: yaml file: params.yaml loaded successfully]
[2025-03-05 16:19:31,094: INFO: common: yaml file: schema.yaml loaded successfully]
[2025-03-05 16:19:31,094: INFO: common: created directory at: artifacts]
[2025-03-05 16:19:31,094: INFO: common: created directory at: artifacts/data_transformation]
[2025-03-05 16:19:31,127: INFO: data_transformation: Splited data into training and test sets]
[2025-03-05 16:19:31,127: INFO: data_transformation: (1199, 12)]
[2025-03-05 16:19:31,127: INFO: data_transformation: (400, 12)]
[2025-03-05 16:19:31,127: INFO: main: >>>>>> stage Data Transformation Stage completed <<<<<

x=======x]
[2025-03-05 16:19:31,127: INFO: main: >>>>> stage Model Training Stage started <<<<<<]
[2025-03-05 16:19:31,130: INFO: common: yaml file: config/config.yaml loaded successfully]
[2025-03-05 16:19:31,131: INFO: common: yaml file: params.yaml loaded successfully]
[2025-03-05 16:19:31,132: INFO: common: yaml file: schema.yaml loaded successfully]
[2025-03-05 16:19:31,132: INFO: common: created directory at: artifacts]
[2025-03-05 16:19:31,132: INFO: common: created directory at: artifacts/model_trainer]
[2025-03-05 16:19:31,154: INFO: main: >>>>>> stage Model Training Stage completed <<<<<

x=======x]
[2025-03-05 16:19:31,154: INFO: main: >>>>> stage Model Evaluation Stage started <<<<<<]
[2025-03-05 16:19:31,158: INFO: common: yaml file: config/config.yaml loaded successfully]
[2025-03-05 16:19:31,159: INFO: common: yaml file: params.yaml loaded successfully]
[2025-03-05 16:19:31,161: INFO: common: yaml file: schema.yaml loaded successfully]
[2025-03-05 16:19:31,161: INFO: common: created directory at: artifacts]
[2025-03-05 16:19:31,161: INFO: common: created directory at: artifacts/model_evaluation]
[2025-03-05 16:19:32,147: INFO: common: json file saved at: artifacts/model_evaluation/metrics.json]
[2025-03-05 16:19:37,656: INFO: main: >>>>>> stage Model Evaluation Stage completed <<<<<

x=======x]
[2025-03-05 16:19:38,208: INFO: _internal: 127.0.0.1 - - [05/Mar/2025 16:19:38] "GET /train HTTP/1.1" 200 -]
[2025-03-05 16:20:36,537: INFO: _internal: 127.0.0.1 - - [05/Mar/2025 16:20:36] "GET / HTTP/1.1" 200 -]
[2025-03-05 16:20:36,564: INFO: _internal: 127.0.0.1 - - [05/Mar/2025 16:20:36] "[33mGET /static/assets/img/form-v9.jpg HTTP/1.1[0m" 404 -]
[2025-03-05 16:20:50,152: INFO: _internal: 127.0.0.1 - - [05/Mar/2025 16:20:50] "POST /predict HTTP/1.1" 200 -]
[2025-03-05 16:21:44,093: INFO: _internal: 192.168.22.204 - - [05/Mar/2025 16:21:44] "GET / HTTP/1.1" 200 -]
[2025-03-05 16:21:44,131: INFO: _internal: 192.168.22.204 - - [05/Mar/2025 16:21:44] "[33mGET /static/assets/img/form-v9.jpg HTTP/1.1[0m" 404 -]
[2025-03-05 16:21:44,244: INFO: _internal: 192.168.22.204 - - [05/Mar/2025 16:21:44] "[33mGET /favicon.ico HTTP/1.1[0m" 404 -]
[2025-03-05 16:21:55,745: INFO: _internal: 192.168.22.204 - - [05/Mar/2025 16:21:55] "POST /predict HTTP/1.1" 200 -]
[2025-03-05 16:28:06,950: INFO: _internal: [31m[1mWARNING: This is a development server. Do not use it in a production deployment. Use a production WSGI server instead.[0m
 * Running on all addresses (0.0.0.0)
 * Running on http://127.0.0.1:8080
 * Running on http://192.168.22.204:8080]
[2025-03-05 16:28:06,951: INFO: _internal: [33mPress CTRL+C to quit[0m]
[2025-03-05 16:28:14,724: INFO: _internal: 127.0.0.1 - - [05/Mar/2025 16:28:14] "GET / HTTP/1.1" 200 -]
[2025-03-05 16:28:14,769: INFO: _internal: 127.0.0.1 - - [05/Mar/2025 16:28:14] "[33mGET /static/assets/img/form-v9.jpg HTTP/1.1[0m" 404 -]
[2025-03-05 16:28:25,269: INFO: main: >>>>> stage Data Ingestion Stage started <<<<<<]
[2025-03-05 16:28:25,273: INFO: common: yaml file: config/config.yaml loaded successfully]
[2025-03-05 16:28:25,279: INFO: common: yaml file: params.yaml loaded successfully]
[2025-03-05 16:28:25,281: INFO: common: yaml file: schema.yaml loaded successfully]
[2025-03-05 16:28:25,283: INFO: common: created directory at: artifacts]
[2025-03-05 16:28:25,284: INFO: common: created directory at: artifacts/data_ingestion]
[2025-03-05 16:28:25,284: INFO: data_ingestion: File already exists]
[2025-03-05 16:28:25,289: INFO: main: >>>>>> stage Data Ingestion Stage completed <<<<<

x=======x]
[2025-03-05 16:28:25,289: INFO: main: >>>>> stage Data Validation Stage started <<<<<<]
[2025-03-05 16:28:25,292: INFO: common: yaml file: config/config.yaml loaded successfully]
[2025-03-05 16:28:25,292: INFO: common: yaml file: params.yaml loaded successfully]
[2025-03-05 16:28:25,294: INFO: common: yaml file: schema.yaml loaded successfully]
[2025-03-05 16:28:25,294: INFO: common: created directory at: artifacts]
[2025-03-05 16:28:25,295: INFO: common: created directory at: artifacts/data_validation]
[2025-03-05 16:28:25,316: INFO: main: >>>>>> stage Data Validation Stage completed <<<<<

x=======x]
[2025-03-05 16:28:25,316: INFO: main: >>>>> stage Data Transformation Stage started <<<<<<]
[2025-03-05 16:28:25,321: INFO: common: yaml file: config/config.yaml loaded successfully]
[2025-03-05 16:28:25,322: INFO: common: yaml file: params.yaml loaded successfully]
[2025-03-05 16:28:25,324: INFO: common: yaml file: schema.yaml loaded successfully]
[2025-03-05 16:28:25,324: INFO: common: created directory at: artifacts]
[2025-03-05 16:28:25,324: INFO: common: created directory at: artifacts/data_transformation]
[2025-03-05 16:28:25,359: INFO: data_transformation: Splited data into training and test sets]
[2025-03-05 16:28:25,359: INFO: data_transformation: (1199, 12)]
[2025-03-05 16:28:25,359: INFO: data_transformation: (400, 12)]
[2025-03-05 16:28:25,359: INFO: main: >>>>>> stage Data Transformation Stage completed <<<<<

x=======x]
[2025-03-05 16:28:25,359: INFO: main: >>>>> stage Model Training Stage started <<<<<<]
[2025-03-05 16:28:25,362: INFO: common: yaml file: config/config.yaml loaded successfully]
[2025-03-05 16:28:25,363: INFO: common: yaml file: params.yaml loaded successfully]
[2025-03-05 16:28:25,366: INFO: common: yaml file: schema.yaml loaded successfully]
[2025-03-05 16:28:25,367: INFO: common: created directory at: artifacts]
[2025-03-05 16:28:25,367: INFO: common: created directory at: artifacts/model_trainer]
[2025-03-05 16:28:25,385: INFO: main: >>>>>> stage Model Training Stage completed <<<<<

x=======x]
[2025-03-05 16:28:25,385: INFO: main: >>>>> stage Model Evaluation Stage started <<<<<<]
[2025-03-05 16:28:25,387: INFO: common: yaml file: config/config.yaml loaded successfully]
[2025-03-05 16:28:25,388: INFO: common: yaml file: params.yaml loaded successfully]
[2025-03-05 16:28:25,390: INFO: common: yaml file: schema.yaml loaded successfully]
[2025-03-05 16:28:25,390: INFO: common: created directory at: artifacts]
[2025-03-05 16:28:25,391: INFO: common: created directory at: artifacts/model_evaluation]
[2025-03-05 16:28:26,398: INFO: common: json file saved at: artifacts/model_evaluation/metrics.json]
[2025-03-05 16:28:31,586: INFO: main: >>>>>> stage Model Evaluation Stage completed <<<<<

x=======x]
[2025-03-05 16:28:32,271: INFO: _internal: 127.0.0.1 - - [05/Mar/2025 16:28:32] "GET /train HTTP/1.1" 200 -]
